Workbook
Name Axis_CO2: #REF!
Name Axis_methane: #REF!
Name BB_Ticker: #REF!
Name BDP_Func: _xll.BDP([0]!BB_Ticker,[0]!ROW_2)
Name BDP_Func: _xll.BDP(BB_Ticker,ROW_2)
Name BDP_Funx: IF(LEFT([0]!BB_Ticker,1)="!",".",IF(LEFT('Production by region'!BDP_Func,1)="#","-",'Production by region'!BDP_Func))
Name BDP_Funx: IF(LEFT(BB_Ticker,1)="!",".",IF(LEFT(BDP_Func,1)="#","-",BDP_Func))
Name BFM_protein_table: 'Additional data sources'!$C$3:$E$6
Name Cap_cattle: 'Additional data sources'!$D$26
Name Cap_pigs: 'Additional data sources'!$D$27
Name Cap_pigs_Pilgrims: 'Additional company data'!$X$39
Name Cap_poultry: 'Additional data sources'!$D$28
Name COL_LET: SUBSTITUTE(ADDRESS(1,COLUMN(),4),"1","")
Name Danone_intake: 'Additional company data'!$G$8
Name days_per_year: 'Additional data sources'!$D$23
Name Dressing_perc: 'Additional data sources'!$C$16:$O$19
Name Emissions_results: #REF!
Name GLEAM_column_index: #REF!
Name GLEAM_GWP100_AR6: #REF!
Name GLEAM_GWP100_UPDATED_w_GLEAM_v3: #REF!
Name GLEAM_GWP20_AR6: #REF!
Name GLEAM_regions: 'Additional data sources'!#REF!
Name GLEAM_row_index: #REF!
Name GWP: 'Additional data sources'!#REF!
Name Milk_prod: 'Production data'!$B$86:$D$114
Name Milk_protein: #REF!
Name Production_systems: 'Additional data sources'!#REF!
Name RF_Company_Name: #REF!
Name RF_Issuer_Ticker_Code: #REF!
Name RF_PermID: #REF!
Name RF_Primary_Equity_ISIN: #REF!
Name RF_Primary_RIC: #REF!
Name ROW_2: INDIRECT(COL_LET&"2")
Name Slaughter_mass: 'Additional data sources'!$C$10:$O$13
Name TermEndDate: '[1]Creditor data'!$AX$1
Name Tot_CH4_GWP100: #REF!
Name Tot_CH4_GWP20: #REF!
Name Tot_GHG_GWP100: #REF!
Name Tot_GHG_GWP20: #REF!
Name TR_Func: _xll.TR([0]!RF_PermID,[0]!ROW_2,"NULL=-")
Name TR_Func: _xll.TR(RF_PermID,ROW_2,"NULL=-")
Name TR_FUNC_on_ISIN1: _xll.TR([0]!RF_Primary_Equity_ISIN,[0]!ROW_2,"NULL=-")
Name TR_FUNC_on_ISIN1: _xll.TR(RF_Primary_Equity_ISIN,ROW_2,"NULL=-")
Name TR_Funx: IF(LEFT([0]!RF_PermID,1)="!",".",IF(LEFT('Production by region'!TR_Func,1)="#","-",'Production by region'!TR_Func))
Name TR_Funx: IF(LEFT(RF_PermID,1)="!",".",IF(LEFT(TR_Func,1)="#","-",TR_Func))

Sheet Overview
A1: Tab Name | B1: Description
A2: Visually processed data for code
A3: Production by region | B3: Production data across animal products, regions, and sources for data
A4: Dairy | B4: Weight of dairy produced by TNCs
A5: Cattle weight | B5: Conversion of heads into weight based on regional unit slaughter weights produced by TNCs
A6: Chickens weight | B6: Conversion of heads into weight based on regional unit slaughter weights produced by TNCs
A7: Pigs weight | B7: Conversion of heads into weight based on regional unit slaughter weights produced by TNCs
A9: Data from Profundo
A10: Production data | B10: Production data across animal products, regions, and sources for data
A11: Additional company data | B11: Information on companies which required more assumptions and analysis
A12: Additional data sources | B12: Information on additional data sources that are required for some production data assumptions

Sheet Production by region
A1: Cattle | E1: Chicken | I1: Pigs | M1: Dairy
A3: Category | B3: (All) | E3: Category | F3: (All) | I3: Category | J3: (All) | Q3: Multiplied by 1000000
Q4: 1000000
A5: Sum of # of heads processed per annum (reported or based on capacity use) | C5: Animal | E5: Sum of # of heads processed per annum (reported or based on capacity use) | G5: Animal | I5: Sum of # of heads processed per annum (reported or based on capacity use) | K5: Animal | M5: Company | N5: Region | O5: Category | P5: Sum of Milk intake (mio tonnes, 2022) | Q5: Dairy
A6: Company | B6: Region | C6: Cattle | E6: Company | F6: Region | G6: Chicken | I6: Company | J6: Region | K6: Pigs | M6: Dairy Farmers of America | N6: North America | O6: Main | P6: 29.7 | Q6: =GETPIVOTDATA("Milk intake (mio tonnes, 2022)",$M$5,"Category","Main"," Company","Dairy Farmers of America","Region","North America")*$Q$4 -> 29700000
A7: Bigard | B7: Western Europe | C7: 1931153 | E7: Arab Company for Livestock Development (ACOLID) | F7: Near East and North Africa | G7: 662200000 | I7: Aurora Alimentos | J7: South America | K7: 7300000 | M7: Lactalis | N7: Western Europe | O7: Main | P7: 22.6 | Q7: =GETPIVOTDATA("Milk intake (mio tonnes, 2022)",$M$5,"Category","Main"," Company","Lactalis","Region","Western Europe")*Q4 -> 22600000
A8: Cargill | B8: North America | C8: 7000000 | E8: Aurora Alimentos | F8: South America | G8: 320800000 | I8: Bigard | J8: Western Europe | K8: 8381962.9 | M8: Fonterra | N8: Oceania | O8: Main | P8: 17.6 | Q8: =GETPIVOTDATA("Milk intake (mio tonnes, 2022)",$M$5,"Category","Main"," Company","Fonterra","Region","Oceania")*Q4 -> 17600000
A9: Cargill | B9: Oceania | C9: 750000 | E9: BRF | F9: South America | G9: 1612145600 | I9: BRF | J9: South America | K9: 9639552 | M9: Arla | N9: Western Europe | O9: Main | P9: 13.5 | Q9: =GETPIVOTDATA("Milk intake (mio tonnes, 2022)",$M$5,"Category","Main"," Company","Arla","Region","Western Europe")*Q4 -> 13500000
A10: Danish Crown | B10: Western Europe | C10: 800000 | E10: Cargill | F10: East Asia and Southeast Asia | G10: 180000000 | I10: Charoen Pokphand | J10: East Asia and Southeast Asia | K10: 1130000 | M10: Nestlé | N10: Western Europe | O10: Main | P10: 13.5 | Q10: =GETPIVOTDATA("Milk intake (mio tonnes, 2022)",$M$5,"Category","Main"," Company","Nestlé","Region","Western Europe")*Q4 -> 13500000
A11: Gruppo Cremonini | B11: Western Europe | C11: 1864145.8 | E11: Cargill | F11: Europe | G11: 144000000 | I11: Charoen Pokphand | J11: North America | K11: 3800000 | M11: Saputo | N11: North America | O11: Main | P11: 11 | Q11: =GETPIVOTDATA("Milk intake (mio tonnes, 2022)",$M$5,"Category","Main"," Company","Saputo","Region","North America")*Q4 -> 11000000
A12: JBS | B12: Latin America and the Caribbean | C12: 9218836.9 | E12: Cargill | F12: Latin America and the Caribbean | G12: 269000000 | I12: Charoen Pokphand | J12: Russian Federation | K12: 2270689.7 | M12: FrieslandCampina | N12: Western Europe | O12: Main | P12: 10.7 | Q12: =GETPIVOTDATA("Milk intake (mio tonnes, 2022)",$M$5,"Category","Main"," Company","FrieslandCampina","Region","Western Europe")*Q4 -> 10700000
A13: JBS | B13: North America | C13: 8958582.4 | E13: Cargill | F13: North America | G13: 535600000 | I13: Clemens Food Group | J13: North America | K13: 3382400 | M13: Yili | N13: East Asia and Southeast Asia | O13: Main | P13: 10 | Q13: =GETPIVOTDATA("Milk intake (mio tonnes, 2022)",$M$5,"Category","Main"," Company","Yili ","Region","East Asia and Southeast Asia")*Q4 -> 10000000
A14: JBS | B14: Oceania | C14: 2637722.4 | E14: Charoen Pokphand | F14: East Asia and Southeast Asia | G14: 685000000 | I14: COFCO Group | J14: East Asia and Southeast Asia | K14: 5200000 | M14: China Mengniu Dairy | N14: China | O14: Main | P14: 9.7 | Q14: =GETPIVOTDATA("Milk intake (mio tonnes, 2022)",$M$5,"Category","Main"," Company","China Mengniu Dairy","Region","China")*Q4 -> 9700000
A15: Marfrig | B15: Latin America and the Caribbean | C15: 4644458 | E15: Charoen Pokphand | F15: Russian Federation | G15: 66347032 | I15: Cooperl Arc Atlantique | J15: Western Europe | K15: 4300000 | M15: Amul | N15: India | O15: Main | P15: 9.6 | Q15: =GETPIVOTDATA("Milk intake (mio tonnes, 2022)",$M$5,"Category","Main"," Company","Amul","Region","India")*Q4 -> 9600000
A16: Marfrig | B16: North America | C16: 3600142 | E16: Continental Grain Company | F16: North America | G16: 535600000 | I16: Danish Crown | J16: Eastern Europe | K16: 1270160 | M16: Glanbia | N16: North America | O16: Main | P16: 9 | Q16: =GETPIVOTDATA("Milk intake (mio tonnes, 2022)",$M$5,"Category","Main"," Company","Glanbia","Region","North America")*Q4 -> 9000000
A17: Minerva | B17: Latin America and the Caribbean | C17: 3873800 | E17: Fuijan Sunner Development | F17: East Asia and Southeast Asia | G17: 680000000 | I17: Danish Crown | J17: Western Europe | K17: 14606840 | M17: California Diaries | N17: North America | O17: Main | P17: 7.7 | Q17: =GETPIVOTDATA("Milk intake (mio tonnes, 2022)",$M$5,"Category","Main"," Company","California Diaries","Region","North America")*Q4 -> 7700000
A18: NH Foods | B18: Oceania | C18: 336859 | E18: Industrias Bachoco | F18: Latin America and the Caribbean | G18: 505000000 | I18: Grupo Jorges | J18: Western Europe | K18: 6400000 | M18: Müller | N18: Western Europe | O18: Main | P18: 6.7 | Q18: =GETPIVOTDATA("Milk intake (mio tonnes, 2022)",$M$5,"Category","Main"," Company","Müller","Region","Western Europe")*Q4 -> 6700000
A19: Teys | B19: Oceania | C19: 750000 | E19: Industrias Bachoco | F19: North America | G19: 135000000 | I19: Grupo Vall | J19: Western Europe | K19: 8505747.1 | M19: Danone-IFCN | N19: Eastern Europe | O19: Main | P19: 0.66775799 | Q19: =GETPIVOTDATA("Milk intake (mio tonnes, 2022)",$M$5,"Category","Main"," Company","Danone-IFCN","Region","Eastern Europe")*Q4 -> 667757.99
A20: Tönnies Group | B20: Western Europe | C20: 364000 | E20: Japfa | F20: East Asia and Southeast Asia | G20: 981000000 | I20: Gruppo Cremonini | J20: Western Europe | K20: 707338.64 | M20: Danone-IFCN | N20: Latin America and the Caribbean | O20: Main | P20: 0.73453379 | Q20: =GETPIVOTDATA("Milk intake (mio tonnes, 2022)",$M$5,"Category","Main"," Company","Danone-IFCN","Region","Latin America and the Caribbean")*Q4 -> 734533.79
A21: Tyson | B21: North America | C21: 5912585.7 | E21: JBS | F21: Latin America and the Caribbean | G21: 1412272800 | I21: JBS | J21: Latin America and the Caribbean | K21: 8813568 | M21: Danone-IFCN | N21: Near East and North Africa | O21: Main | P21: 0.48968919 | Q21: =GETPIVOTDATA("Milk intake (mio tonnes, 2022)",$M$5,"Category","Main"," Company","Danone-IFCN","Region","Near East and North Africa")*Q4 -> 489689.19
A22: Tyson | B22: Oceania | C22: 454814.29 | E22: JBS | F22: North America | G22: 1.802559e+09 | I22: JBS | J22: North America | K22: 26846592 | M22: Danone-IFCN | N22: North America | O22: Main | P22: 1.9364982 | Q22: =GETPIVOTDATA("Milk intake (mio tonnes, 2022)",$M$5,"Category","Main"," Company","Danone-IFCN","Region","North America")*Q4 -> 1936498.2
A23: Vion Food Group | B23: Western Europe | C23: 910000 | E23: JBS | F23: Western Europe | G23: 3.9430978e+08 | I23: JBS | J23: Oceania | K23: 3090547.2 | M23: Danone-IFCN | N23: Russian Federation | O23: Main | P23: 1.5358434 | Q23: =GETPIVOTDATA("Milk intake (mio tonnes, 2022)",$M$5,"Category","Main"," Company","Danone-IFCN","Region","Russian Federation")*Q4 -> 1535843.4
A24: Westfleisch | B24: Western Europe | C24: 380800 | E24: Koch Foods | F24: North America | G24: 670000000 | I24: JBS | J24: Western Europe | K24: 2036053.8 | M24: Danone-IFCN | N24: Sub-Saharan Africa | O24: Main | P24: 0.26726468 | Q24: =GETPIVOTDATA("Milk intake (mio tonnes, 2022)",$M$5,"Category","Main"," Company","Danone-IFCN","Region","Sub-Saharan Africa")*Q4 -> 267264.68
A25: Grand Total | C25: 54387899 | E25: MHP | F25: Eastern Europe | G25: 438443556 | I25: Muyuan Foodstuff | J25: East Asia and Southeast Asia | K25: 13260000 | M25: Danone-IFCN | N25: Western Europe | O25: Main | P25: 1.0684128 | Q25: =GETPIVOTDATA("Milk intake (mio tonnes, 2022)",$M$5,"Category","Main"," Company","Danone-IFCN","Region","Western Europe")*Q4 -> 1068412.8
E26: New Hope Group | F26: East Asia and Southeast Asia | G26: 657780000 | I26: New Hope Group | J26: East Asia and Southeast Asia | K26: 3960000 | M26: Agropur | N26: North America | O26: Main | P26: 6.7 | Q26: =GETPIVOTDATA("Milk intake (mio tonnes, 2022)",$M$5,"Category","Main"," Company","Agropur","Region","North America")*Q4 -> 6700000
E27: Perdue Farms | F27: North America | G27: 615000000 | I27: Seaboard | J27: North America | K27: 6000000 | M27: DMK | N27: Western Europe | O27: Addition | P27: 5.5 | Q27: =GETPIVOTDATA("Milk intake (mio tonnes, 2022)",$M$5,"Category","Addition"," Company","DMK","Region","Western Europe")*Q4 -> 5500000
E28: Tyson | F28: East Asia and Southeast Asia | G28: 2.0883871e+08 | I28: Tönnies Group | J28: Western Europe | K28: 17790000 | M28: Grand Total | P28: 190.2 | Q28: =SUM(Q6:Q27) -> 190200000
E29: Tyson | F29: North America | G29: 1.7333613e+09 | I29: Triumph Foods | J29: North America | K29: 5200000
E30: Wellhope Agritech | F30: East Asia and Southeast Asia | G30: 810000000 | I30: Tyson | J30: North America | K30: 20573280
E31: Wen's Food Group | F31: East Asia and Southeast Asia | G31: 1183000000 | I31: Vion Food Group | J31: Western Europe | K31: 15222482
E32: WH Group | F32: East Asia and Southeast Asia | G32: 2.0933333e+08 | I32: Wen's Food Group | J32: East Asia and Southeast Asia | K32: 3840000
E33: WH Group | F33: Eastern Europe | G33: 1.0466667e+08 | I33: Westfleisch | J33: Western Europe | K33: 6600000
E34: Grand Total | G34: 1.7551258e+10 | I34: WH Group | J34: East Asia and Southeast Asia | K34: 13177939
I35: WH Group | J35: Eastern Europe | K35: 6260571.4
I36: WH Group | J36: North America | K36: 29730490
I37: Zhengbang Group | J37: East Asia and Southeast Asia | K37: 8450000
I38: Grand Total | K38: 2.6774621e+08

Sheet Dairy
A1: ='Production by region'!M5 -> Company | B1: ='Production by region'!N5 -> Region | C1: ='Production by region'!Q5 -> Dairy
A2: ='Production by region'!M6 -> Dairy Farmers of America | B2: ='Production by region'!N6 -> North America | C2: ='Production by region'!Q6 -> 29700000
A3: ='Production by region'!M7 -> Lactalis | B3: ='Production by region'!N7 -> Western Europe | C3: ='Production by region'!Q7 -> 22600000
A4: ='Production by region'!M8 -> Fonterra | B4: ='Production by region'!N8 -> Oceania | C4: ='Production by region'!Q8 -> 17600000
A5: ='Production by region'!M9 -> Arla | B5: ='Production by region'!N9 -> Western Europe | C5: ='Production by region'!Q9 -> 13500000
A6: ='Production by region'!M10 -> Nestlé | B6: ='Production by region'!N10 -> Western Europe | C6: ='Production by region'!Q10 -> 13500000
A7: ='Production by region'!M11 -> Saputo | B7: ='Production by region'!N11 -> North America | C7: ='Production by region'!Q11 -> 11000000
A8: ='Production by region'!M12 -> FrieslandCampina | B8: ='Production by region'!N12 -> Western Europe | C8: ='Production by region'!Q12 -> 10700000
A9: ='Production by region'!M13 -> Yili | B9: ='Production by region'!N13 -> East Asia and Southeast Asia | C9: ='Production by region'!Q13 -> 10000000
A10: ='Production by region'!M14 -> China Mengniu Dairy | B10: East Asia and Southeast Asia | C10: ='Production by region'!Q14 -> 9700000
A11: ='Production by region'!M15 -> Amul | B11: South Asia | C11: ='Production by region'!Q15 -> 9600000
A12: ='Production by region'!M16 -> Glanbia | B12: ='Production by region'!N16 -> North America | C12: ='Production by region'!Q16 -> 9000000
A13: ='Production by region'!M17 -> California Diaries | B13: ='Production by region'!N17 -> North America | C13: ='Production by region'!Q17 -> 7700000
A14: ='Production by region'!M18 -> Müller | B14: ='Production by region'!N18 -> Western Europe | C14: ='Production by region'!Q18 -> 6700000
A15: ='Production by region'!M19 -> Danone-IFCN | B15: ='Production by region'!N19 -> Eastern Europe | C15: ='Production by region'!Q19 -> 667757.99
A16: ='Production by region'!M20 -> Danone-IFCN | B16: ='Production by region'!N20 -> Latin America and the Caribbean | C16: ='Production by region'!Q20 -> 734533.79
A17: ='Production by region'!M21 -> Danone-IFCN | B17: ='Production by region'!N21 -> Near East and North Africa | C17: ='Production by region'!Q21 -> 489689.19
A18: ='Production by region'!M22 -> Danone-IFCN | B18: ='Production by region'!N22 -> North America | C18: ='Production by region'!Q22 -> 1936498.2
A19: ='Production by region'!M23 -> Danone-IFCN | B19: ='Production by region'!N23 -> Russian Federation | C19: ='Production by region'!Q23 -> 1535843.4
A20: ='Production by region'!M24 -> Danone-IFCN | B20: ='Production by region'!N24 -> Sub-Saharan Africa | C20: ='Production by region'!Q24 -> 267264.68
A21: ='Production by region'!M25 -> Danone-IFCN | B21: ='Production by region'!N25 -> Western Europe | C21: ='Production by region'!Q25 -> 1068412.8
A22: ='Production by region'!M26 -> Agropur | B22: ='Production by region'!N26 -> North America | C22: ='Production by region'!Q26 -> 6700000
A23: ='Production by region'!M27 -> DMK | B23: ='Production by region'!N27 -> Western Europe | C23: ='Production by region'!Q27 -> 5500000

Sheet Cattle weight
A1: ='Production by region'!A6 -> Company | B1: ='Production by region'!B6 -> Region | C1: Cattle weight | D1: Cattle count | E1: Cattle unit slaughter weight (t)
A2: ='Production by region'!A7 -> Bigard | B2: ='Production by region'!B7 -> Western Europe | C2: =D2*E2 -> 1025442.3 | D2: ='Production by region'!C7 -> 1931153 | E2: =INDEX('Additional data sources'!$F$11:$O$11,MATCH(B2,'Additional data sources'!$F$10:$O$10,0))/1000 -> 0.531
A3: ='Production by region'!A8 -> Cargill | B3: ='Production by region'!B8 -> North America | C3: =D3*E3 -> 4187166.7 | D3: ='Production by region'!C8 -> 7000000 | E3: =INDEX('Additional data sources'!$F$11:$O$11,MATCH(B3,'Additional data sources'!$F$10:$O$10,0))/1000 -> 0.59816667
A4: ='Production by region'!A9 -> Cargill | B4: ='Production by region'!B9 -> Oceania | C4: =D4*E4 -> 286500 | D4: ='Production by region'!C9 -> 750000 | E4: =INDEX('Additional data sources'!$F$11:$O$11,MATCH(B4,'Additional data sources'!$F$10:$O$10,0))/1000 -> 0.382
A5: ='Production by region'!A10 -> Danish Crown | B5: ='Production by region'!B10 -> Western Europe | C5: =D5*E5 -> 424800 | D5: ='Production by region'!C10 -> 800000 | E5: =INDEX('Additional data sources'!$F$11:$O$11,MATCH(B5,'Additional data sources'!$F$10:$O$10,0))/1000 -> 0.531
A6: ='Production by region'!A11 -> Gruppo Cremonini | B6: ='Production by region'!B11 -> Western Europe | C6: =D6*E6 -> 989861.41 | D6: ='Production by region'!C11 -> 1864145.8 | E6: =INDEX('Additional data sources'!$F$11:$O$11,MATCH(B6,'Additional data sources'!$F$10:$O$10,0))/1000 -> 0.531
A7: ='Production by region'!A12 -> JBS | B7: ='Production by region'!B12 -> Latin America and the Caribbean | C7: =D7*E7 -> 4143867.2 | D7: ='Production by region'!C12 -> 9218836.9 | E7: =INDEX('Additional data sources'!$F$11:$O$11,MATCH(B7,'Additional data sources'!$F$10:$O$10,0))/1000 -> 0.4495
A8: ='Production by region'!A13 -> JBS | B8: ='Production by region'!B13 -> North America | C8: =D8*E8 -> 5358725.3 | D8: ='Production by region'!C13 -> 8958582.4 | E8: =INDEX('Additional data sources'!$F$11:$O$11,MATCH(B8,'Additional data sources'!$F$10:$O$10,0))/1000 -> 0.59816667
A9: ='Production by region'!A14 -> JBS | B9: ='Production by region'!B14 -> Oceania | C9: =D9*E9 -> 1007609.9 | D9: ='Production by region'!C14 -> 2637722.4 | E9: =INDEX('Additional data sources'!$F$11:$O$11,MATCH(B9,'Additional data sources'!$F$10:$O$10,0))/1000 -> 0.382
A10: ='Production by region'!A15 -> Marfrig | B10: ='Production by region'!B15 -> Latin America and the Caribbean | C10: =D10*E10 -> 2087683.9 | D10: ='Production by region'!C15 -> 4644458 | E10: =INDEX('Additional data sources'!$F$11:$O$11,MATCH(B10,'Additional data sources'!$F$10:$O$10,0))/1000 -> 0.4495
A11: ='Production by region'!A16 -> Marfrig | B11: ='Production by region'!B16 -> North America | C11: =D11*E11 -> 2153484.9 | D11: ='Production by region'!C16 -> 3600142 | E11: =INDEX('Additional data sources'!$F$11:$O$11,MATCH(B11,'Additional data sources'!$F$10:$O$10,0))/1000 -> 0.59816667
A12: ='Production by region'!A17 -> Minerva | B12: ='Production by region'!B17 -> Latin America and the Caribbean | C12: =D12*E12 -> 1741273.1 | D12: ='Production by region'!C17 -> 3873800 | E12: =INDEX('Additional data sources'!$F$11:$O$11,MATCH(B12,'Additional data sources'!$F$10:$O$10,0))/1000 -> 0.4495
A13: ='Production by region'!A18 -> NH Foods | B13: ='Production by region'!B18 -> Oceania | C13: =D13*E13 -> 128680.14 | D13: ='Production by region'!C18 -> 336859 | E13: =INDEX('Additional data sources'!$F$11:$O$11,MATCH(B13,'Additional data sources'!$F$10:$O$10,0))/1000 -> 0.382
... A19: ='Production by region'!A24 -> Westfleisch | B19: ='Production by region'!B24 -> Western Europe | C19: =D19*E19 -> 202204.8 | D19: ='Production by region'!C24 -> 380800 | E19: =INDEX('Additional data sources'!$F$11:$O$11,MATCH(B19,'Additional data sources'!$F$10:$O$10,0))/1000 -> 0.531

Sheet Chickens weight
A1: ='Production by region'!E6 -> Company | B1: ='Production by region'!F6 -> Region | C1: Chickens weight | D1: Chickens count | E1: Chickens unit slaughter weight (t)
A2: ='Production by region'!E7 -> Arab Company for Livestock Development (ACOLID) | B2: ='Production by region'!F7 -> Near East and North Africa | C2: =D2*E2 -> 1238314 | D2: ='Production by region'!G7 -> 662200000 | E2: =INDEX('Additional data sources'!$F$13:$O$13,MATCH(B2,'Additional data sources'!$F$10:$O$10,0))/1000 -> 0.00187
A3: ='Production by region'!E8 -> Aurora Alimentos | B3: Latin America and the Caribbean | C3: =D3*E3 -> 792376 | D3: ='Production by region'!G8 -> 320800000 | E3: =INDEX('Additional data sources'!$F$13:$O$13,MATCH(B3,'Additional data sources'!$F$10:$O$10,0))/1000 -> 0.00247
A4: ='Production by region'!E9 -> BRF | B4: Latin America and the Caribbean | C4: =D4*E4 -> 3981999.6 | D4: ='Production by region'!G9 -> 1612145600 | E4: =INDEX('Additional data sources'!$F$13:$O$13,MATCH(B4,'Additional data sources'!$F$10:$O$10,0))/1000 -> 0.00247
A5: ='Production by region'!E10 -> Cargill | B5: ='Production by region'!F10 -> East Asia and Southeast Asia | C5: =D5*E5 -> 340200 | D5: ='Production by region'!G10 -> 180000000 | E5: =INDEX('Additional data sources'!$F$13:$O$13,MATCH(B5,'Additional data sources'!$F$10:$O$10,0))/1000 -> 0.00189
A6: ='Production by region'!E11 -> Cargill | B6: Western Europe | C6: =D6*E6 -> 335520 | D6: ='Production by region'!G11 -> 144000000 | E6: =INDEX('Additional data sources'!$F$13:$O$13,MATCH(B6,'Additional data sources'!$F$10:$O$10,0))/1000 -> 0.00233
A7: ='Production by region'!E12 -> Cargill | B7: ='Production by region'!F12 -> Latin America and the Caribbean | C7: =D7*E7 -> 664430 | D7: ='Production by region'!G12 -> 269000000 | E7: =INDEX('Additional data sources'!$F$13:$O$13,MATCH(B7,'Additional data sources'!$F$10:$O$10,0))/1000 -> 0.00247
A8: ='Production by region'!E13 -> Cargill | B8: ='Production by region'!F13 -> North America | C8: =D8*E8 -> 1430052 | D8: ='Production by region'!G13 -> 535600000 | E8: =INDEX('Additional data sources'!$F$13:$O$13,MATCH(B8,'Additional data sources'!$F$10:$O$10,0))/1000 -> 0.00267
A9: ='Production by region'!E14 -> Charoen Pokphand | B9: ='Production by region'!F14 -> East Asia and Southeast Asia | C9: =D9*E9 -> 1294650 | D9: ='Production by region'!G14 -> 685000000 | E9: =INDEX('Additional data sources'!$F$13:$O$13,MATCH(B9,'Additional data sources'!$F$10:$O$10,0))/1000 -> 0.00189
A10: ='Production by region'!E15 -> Charoen Pokphand | B10: ='Production by region'!F15 -> Russian Federation | C10: =D10*E10 -> 145300 | D10: ='Production by region'!G15 -> 66347032 | E10: =INDEX('Additional data sources'!$F$13:$O$13,MATCH(B10,'Additional data sources'!$F$10:$O$10,0))/1000 -> 0.00219
A11: ='Production by region'!E16 -> Continental Grain Company | B11: ='Production by region'!F16 -> North America | C11: =D11*E11 -> 1430052 | D11: ='Production by region'!G16 -> 535600000 | E11: =INDEX('Additional data sources'!$F$13:$O$13,MATCH(B11,'Additional data sources'!$F$10:$O$10,0))/1000 -> 0.00267
A12: ='Production by region'!E17 -> Fuijan Sunner Development | B12: ='Production by region'!F17 -> East Asia and Southeast Asia | C12: =D12*E12 -> 1285200 | D12: ='Production by region'!G17 -> 680000000 | E12: =INDEX('Additional data sources'!$F$13:$O$13,MATCH(B12,'Additional data sources'!$F$10:$O$10,0))/1000 -> 0.00189
A13: ='Production by region'!E18 -> Industrias Bachoco | B13: ='Production by region'!F18 -> Latin America and the Caribbean | C13: =D13*E13 -> 1247350 | D13: ='Production by region'!G18 -> 505000000 | E13: =INDEX('Additional data sources'!$F$13:$O$13,MATCH(B13,'Additional data sources'!$F$10:$O$10,0))/1000 -> 0.00247
A14: ='Production by region'!E19 -> Industrias Bachoco | B14: ='Production by region'!F19 -> North America | C14: =D14*E14 -> 360450 | D14: ='Production by region'!G19 -> 135000000 | E14: =INDEX('Additional data sources'!$F$13:$O$13,MATCH(B14,'Additional data sources'!$F$10:$O$10,0))/1000 -> 0.00267
A15: ='Production by region'!E20 -> Japfa | B15: ='Production by region'!F20 -> East Asia and Southeast Asia | C15: =D15*E15 -> 1854090 | D15: ='Production by region'!G20 -> 981000000 | E15: =INDEX('Additional data sources'!$F$13:$O$13,MATCH(B15,'Additional data sources'!$F$10:$O$10,0))/1000 -> 0.00189
A16: ='Production by region'!E21 -> JBS | B16: ='Production by region'!F21 -> Latin America and the Caribbean | C16: =D16*E16 -> 3488313.8 | D16: ='Production by region'!G21 -> 1412272800 | E16: =INDEX('Additional data sources'!$F$13:$O$13,MATCH(B16,'Additional data sources'!$F$10:$O$10,0))/1000 -> 0.00247
A17: ='Production by region'!E22 -> JBS | B17: ='Production by region'!F22 -> North America | C17: =D17*E17 -> 4812832.6 | D17: ='Production by region'!G22 -> 1.802559e+09 | E17: =INDEX('Additional data sources'!$F$13:$O$13,MATCH(B17,'Additional data sources'!$F$10:$O$10,0))/1000 -> 0.00267
A18: ='Production by region'!E23 -> JBS | B18: ='Production by region'!F23 -> Western Europe | C18: =D18*E18 -> 918741.8 | D18: ='Production by region'!G23 -> 3.9430978e+08 | E18: =INDEX('Additional data sources'!$F$13:$O$13,MATCH(B18,'Additional data sources'!$F$10:$O$10,0))/1000 -> 0.00233
... A28: ='Production by region'!E33 -> WH Group | B28: ='Production by region'!F33 -> Eastern Europe | C28: =D28*E28 -> 229220 | D28: ='Production by region'!G33 -> 1.0466667e+08 | E28: =INDEX('Additional data sources'!$F$13:$O$13,MATCH(B28,'Additional data sources'!$F$10:$O$10,0))/1000 -> 0.00219

Sheet Pigs weight
A1: ='Production by region'!I6 -> Company | B1: ='Production by region'!J6 -> Region | C1: Pigs weight | D1: Pigs count | E1: Pigs unit slaughter weight (t)
A2: ='Production by region'!I7 -> Aurora Alimentos | B2: Latin America and the Caribbean | C2: =D2*E2 -> 839500 | D2: ='Production by region'!K7 -> 7300000 | E2: =INDEX('Additional data sources'!$F$12:$O$12,MATCH(B2,'Additional data sources'!$F$10:$O$10,0))/1000 -> 0.115
A3: ='Production by region'!I8 -> Bigard | B3: ='Production by region'!J8 -> Western Europe | C3: =D3*E3 -> 972307.69 | D3: ='Production by region'!K8 -> 8381962.9 | E3: =INDEX('Additional data sources'!$F$12:$O$12,MATCH(B3,'Additional data sources'!$F$10:$O$10,0))/1000 -> 0.116
A4: ='Production by region'!I9 -> BRF | B4: Latin America and the Caribbean | C4: =D4*E4 -> 1108548.5 | D4: ='Production by region'!K9 -> 9639552 | E4: =INDEX('Additional data sources'!$F$12:$O$12,MATCH(B4,'Additional data sources'!$F$10:$O$10,0))/1000 -> 0.115
A5: ='Production by region'!I10 -> Charoen Pokphand | B5: ='Production by region'!J10 -> East Asia and Southeast Asia | C5: =D5*E5 -> 127690 | D5: ='Production by region'!K10 -> 1130000 | E5: =INDEX('Additional data sources'!$F$12:$O$12,MATCH(B5,'Additional data sources'!$F$10:$O$10,0))/1000 -> 0.113
A6: ='Production by region'!I11 -> Charoen Pokphand | B6: ='Production by region'!J11 -> North America | C6: =D6*E6 -> 437000 | D6: ='Production by region'!K11 -> 3800000 | E6: =INDEX('Additional data sources'!$F$12:$O$12,MATCH(B6,'Additional data sources'!$F$10:$O$10,0))/1000 -> 0.115
A7: ='Production by region'!I12 -> Charoen Pokphand | B7: ='Production by region'!J12 -> Russian Federation | C7: =D7*E7 -> 263400 | D7: ='Production by region'!K12 -> 2270689.7 | E7: =INDEX('Additional data sources'!$F$12:$O$12,MATCH(B7,'Additional data sources'!$F$10:$O$10,0))/1000 -> 0.116
A8: ='Production by region'!I13 -> Clemens Food Group | B8: ='Production by region'!J13 -> North America | C8: =D8*E8 -> 388976 | D8: ='Production by region'!K13 -> 3382400 | E8: =INDEX('Additional data sources'!$F$12:$O$12,MATCH(B8,'Additional data sources'!$F$10:$O$10,0))/1000 -> 0.115
A9: ='Production by region'!I14 -> COFCO Group | B9: ='Production by region'!J14 -> East Asia and Southeast Asia | C9: =D9*E9 -> 587600 | D9: ='Production by region'!K14 -> 5200000 | E9: =INDEX('Additional data sources'!$F$12:$O$12,MATCH(B9,'Additional data sources'!$F$10:$O$10,0))/1000 -> 0.113
A10: ='Production by region'!I15 -> Cooperl Arc Atlantique | B10: ='Production by region'!J15 -> Western Europe | C10: =D10*E10 -> 498800 | D10: ='Production by region'!K15 -> 4300000 | E10: =INDEX('Additional data sources'!$F$12:$O$12,MATCH(B10,'Additional data sources'!$F$10:$O$10,0))/1000 -> 0.116
A11: ='Production by region'!I16 -> Danish Crown | B11: ='Production by region'!J16 -> Eastern Europe | C11: =D11*E11 -> 147338.56 | D11: ='Production by region'!K16 -> 1270160 | E11: =INDEX('Additional data sources'!$F$12:$O$12,MATCH(B11,'Additional data sources'!$F$10:$O$10,0))/1000 -> 0.116
A12: ='Production by region'!I17 -> Danish Crown | B12: ='Production by region'!J17 -> Western Europe | C12: =D12*E12 -> 1694393.4 | D12: ='Production by region'!K17 -> 14606840 | E12: =INDEX('Additional data sources'!$F$12:$O$12,MATCH(B12,'Additional data sources'!$F$10:$O$10,0))/1000 -> 0.116
A13: ='Production by region'!I18 -> Grupo Jorges | B13: ='Production by region'!J18 -> Western Europe | C13: =D13*E13 -> 742400 | D13: ='Production by region'!K18 -> 6400000 | E13: =INDEX('Additional data sources'!$F$12:$O$12,MATCH(B13,'Additional data sources'!$F$10:$O$10,0))/1000 -> 0.116
A14: ='Production by region'!I19 -> Grupo Vall | B14: ='Production by region'!J19 -> Western Europe | C14: =D14*E14 -> 986666.67 | D14: ='Production by region'!K19 -> 8505747.1 | E14: =INDEX('Additional data sources'!$F$12:$O$12,MATCH(B14,'Additional data sources'!$F$10:$O$10,0))/1000 -> 0.116
A15: ='Production by region'!I20 -> Gruppo Cremonini | B15: ='Production by region'!J20 -> Western Europe | C15: =D15*E15 -> 82051.282 | D15: ='Production by region'!K20 -> 707338.64 | E15: =INDEX('Additional data sources'!$F$12:$O$12,MATCH(B15,'Additional data sources'!$F$10:$O$10,0))/1000 -> 0.116
A16: ='Production by region'!I21 -> JBS | B16: ='Production by region'!J21 -> Latin America and the Caribbean | C16: =D16*E16 -> 1013560.3 | D16: ='Production by region'!K21 -> 8813568 | E16: =INDEX('Additional data sources'!$F$12:$O$12,MATCH(B16,'Additional data sources'!$F$10:$O$10,0))/1000 -> 0.115
... A32: ='Production by region'!I37 -> Zhengbang Group | B32: ='Production by region'!J37 -> East Asia and Southeast Asia | C32: =D32*E32 -> 954850 | D32: ='Production by region'!K37 -> 8450000 | E32: =INDEX('Additional data sources'!$F$12:$O$12,MATCH(B32,'Additional data sources'!$F$10:$O$10,0))/1000 -> 0.113

Sheet Production data
B1: Table 4.1: Production data - meat | G1: GP update
G2: New data
G4: Underlying data source
A5: Category | B5: Company | C5: HQ country | D5: Animal | E5: Region | F5: Country | G5: Reported processing per annum (in # of heads) | H5: Processing capacity (in # of heads) | I5: # of heads processed per annum (reported or based on capacity use) | J5: Data year | K5: Comments | L5: Data source | M5: Link
A6: Main | B6: JBS | C6: US | D6: Cattle | E6: Latin America and the Caribbean | F6: BR | G6: n/a | H6: 33,545 daily | I6: ='Additional company data'!C38*days_per_year*Cap_cattle -> 9218836.9 | J6: 2023 | K6: Industry average for capacity use; disaggregating cross-regional production based on brand distribution. | L6: See Table 5.5 to 5.8 on Tab 5.1-5.16. Company data; Company reports and presentations
A7: Main | B7: JBS | C7: US | D7: Cattle | E7: North America | F7: multiple | G7: n/a | H7: est. daily cap. | I7: ='Additional company data'!D38*days_per_year*Cap_cattle*SUM('Additional company data'!I38,'Additional company data'!K38)/SUM('Additional company data'!I38:L38) -> 8958582.4 | J7: 2023 | K7: Industry average for capacity use; disaggregating cross-regional production based on brand distribution. | L7: See Table 5.5 to 5.8 on Tab 5.1-5.16. Company data; Company reports and presentations
A8: Main | B8: JBS | C8: US | D8: Cattle | E8: Oceania | F8: multiple | G8: n/a | H8: est. daily cap. | I8: ='Additional company data'!D38*days_per_year*Cap_cattle*'Additional company data'!L38/SUM('Additional company data'!I38:L38) -> 2637722.4 | J8: 2023 | K8: Industry average for capacity use. | L8: See Table 5.5 to 5.8 on Tab 5.1-5.16. Company data; Company reports and presentations
A9: Main | B9: Marfrig | C9: BR | D9: Cattle | E9: Latin America and the Caribbean | F9: multiple | G9: n/a | H9: 16,900 daily | I9: =16900*days_per_year*Cap_cattle -> 4644458 | J9: 2023 | K9: Industry average for capacity use. | L9: Marfrig (2024), Institutional Presentation 1st Quarter 2024, p.21 | M9: https://api.mziq.com/mzfilemanager/v2/d/b8180300-b881-4e6c-b970-12ad72a86ec8/4ec125cf-a0b8-169d-05f0-6cce9979d041?origin=1
A10: Main | B10: Marfrig | C10: BR | D10: Cattle | E10: North America | F10: US | G10: n/a | H10: 13,100 daily | I10: =13100*days_per_year*Cap_cattle -> 3600142 | J10: 2023 | K10: Industry average for capacity use. | L10: Marfrig (2024), Institutional Presentation 1st Quarter 2024, p.15 | M10: https://api.mziq.com/mzfilemanager/v2/d/b8180300-b881-4e6c-b970-12ad72a86ec8/4ec125cf-a0b8-169d-05f0-6cce9979d041?origin=1
A11: Main | B11: Cargill | C11: US | D11: Cattle | E11: North America | F11: multiple | G11: 7000000 | I11: =G11 -> 7000000 | J11: no date | K11: More than 7 mln processed annually. | L11: Cargill (n.d.), Sustainable beef - Our presence. | M11: https://www.cargill.com/sustainability/sustainable-beef
A12: Main | B12: Cargill | C12: US | D12: Cattle | E12: Oceania | F12: AU | G12: =1500000*50% -> 750000 | I12: =G12 -> 750000 | J12: 2023 | K12: JV between Cargill and Teys family. Assigned 50% to each. | L12: Teys (2024), Sustainability Summary Report 2023, p.4 | M12: https://au.teysgroup.com/wp-content/uploads/2024/05/Teys-Australia-Summary-Sustainability-Report-2023.pdf
A13: Main | B13: Tyson | C13: US | D13: Cattle | E13: North America | F13: US | G13: n/a | H13: est. daily cap. | I13: ='Additional company data'!C45*52*'Additional company data'!D45*'Additional company data'!E45 -> 5912585.7 | J13: 2023 | K13: Company-reported capacity use; disaggregating cross-regional production based on facility distribution. | L13: See Table 5.5 to 5.8 on Tab 5.1-5.16. Company data; Tyson 2023 Annual Report on Form 10-K, Item 2 | M13: https://s203.q4cdn.com/483587180/files/doc_financials/annual/2023/tsn-2023-10k-final.pdf
A14: Main | B14: Tyson | C14: US | D14: Cattle | E14: Oceania | F14: AU | G14: n/a | H14: est. daily cap. | I14: ='Additional company data'!C45*52*'Additional company data'!D45*'Additional company data'!F45 -> 454814.29 | J14: 2023 | K14: Company-reported capacity use; disaggregating cross-regional production based on facility distribution. | L14: See Table 5.5 to 5.8 on Tab 5.1-5.16. Company data; Tyson 2023 Annual Report on Form 10-K, Item 2 | M14: https://s203.q4cdn.com/483587180/files/doc_financials/annual/2023/tsn-2023-10k-final.pdf
A15: Main | B15: Minerva | C15: BR | D15: Cattle | E15: Latin America and the Caribbean | F15: multiple | G15: 3873800 | I15: =G15 -> 3873800 | J15: 2023 | L15: Minerva (2024), Earnings Release 4Q23 & 2023, p.5 | M15: https://api.mziq.com/mzfilemanager/v2/d/7f2b381f-831b-4aed-b111-417a5585b53b/4031d53c-e227-9b02-f391-39a45b5a41a9?origin=1
A16: Main | B16: Bigard | C16: FR | D16: Cattle | E16: Western Europe | F16: FR | G16: ='Additional company data'!F67 -> 1931153 | I16: =G16 -> 1931153 | J16: 2023 | K16: Converted from processed meat weight. | L16: See Table 5.13 on Tab 5.1-5.16. Company data; Bigard (2024), 2023 Sustainability Rreport, p.10 | M16: https://www.groupebigard.fr/sites/default/files/medias/2024-07/bigard-dpef2023-pp-bd.pdf
A17: Main | B17: Gruppo Cremonini | C17: IT | D17: Cattle | E17: Western Europe | F17: IT | G17: ='Additional company data'!F52 -> 1864145.8 | I17: =G17 -> 1864145.8 | J17: 2022 | K17: Converted from processed meat weight; Inalca is Cremoninis beef business. | L17: See Table 5.10 on Tab 5.1-5.16. Company data; Company communication; Inalca (2024), Sustainable Supply Chain, p.5 | M17: https://www.inalca.it/wp-content/uploads/2024/01/Integrated-and-Sustainable-Supply-chain.pdf
A18: Main | B18: Vion Food Group | C18: NL | D18: Cattle | E18: Western Europe | F18: multiple | G18: =17500*52 -> 910000 | I18: =G18 -> 910000 | J18: 2023 | K18: Approx. 17,500 processed weekly. | L18: Vion Food Group (n.d.), Vion beef. | M18: https://www.vionfoodgroup.com/en/beef
A19: Main | B19: Danish Crown | C19: DK | D19: Cattle | E19: Western Europe | F19: multiple | G19: 800000 | I19: =G19 -> 800000 | J19: 2023 | L19: Danish Crown Annual Report 2022-2023, p. 4; Danish Crown Annual Report 2019/20 | M19: https://www.danishcrown.com/en-gb/about-us/our-results/annual-reports/; *reporting period October 2020-September 2021
A20: Main | B20: Teys | C20: AU | D20: Cattle | E20: Oceania | F20: multiple | G20: =1500000*50% -> 750000 | I20: =G20 -> 750000 | J20: 2023 | K20: JV between Cargill and Teys family. Assigned 50% to each. | L20: Teys (2024), Sustainability Summary Report 2023, p.4 | M20: https://au.teysgroup.com/wp-content/uploads/2024/05/Teys-Australia-Summary-Sustainability-Report-2023.pdf
A21: Addition | B21: Westfleisch | C21: DE | D21: Cattle | E21: Western Europe | F21: DE | G21: 380800 | I21: =G21 -> 380800 | J21: 2023 | L21: Westfleisch (2024), Geschäftsbericht 2023 [German], p.2 | M21: https://www.westfleisch.de/fileadmin/Bilder/02_Unternehmen/02.07_Archiv/02.07.01_Geschaeftsberichte/2023/Westfleisch_SCE_GeschBericht_2023_web.pdf
A22: Addition | B22: Tönnies Group | C22: DE | D22: Cattle | E22: Western Europe | F22: multiple | G22: =7000*52 -> 364000 | I22: =G22 -> 364000 | J22: 2023 | K22: 7,000 weekly. Announced in Sept. 2024 agreement in principle to take over Vion's cattle slaughter in Germany. | L22: Süddeutsche Zeitung (2024, September 6), Tönnies macht Muh [German].
A23: Addition | B23: NH Foods | C23: JP | D23: Cattle | E23: Oceania | F23: AU | G23: 336859 | I23: =G23 -> 336859 | J23: 2023 | L23: NH Foods (2024), Annual Report 2023, p.54 | M23: https://www.nipponham.co.jp/eng/ir/library/annual/pdf/2024_annual/annual2024all_e.pdf
A24: Main | B24: JBS | C24: BR | D24: Chicken | E24: North America | F24: multiple | G24: n/a | H24: est. daily cap. | I24: ='Additional company data'!E40*days_per_year*Cap_poultry*'Additional company data'!S38/SUM('Additional company data'!S38:S39) -> 1.802559e+09 | J24: 2023 | K24: Industry average for capacity use; disaggregating cross-regional production based on brand distribution. | L24: See Table 5.5 to 5.8 on Tab 5.1-5.16. Company data; Company reports and presentations
A25: Main | B25: JBS | C25: BR | D25: Chicken | E25: Latin America and the Caribbean | F25: BR | G25: n/a | H25: 5.4 mln daily | I25: ='Additional company data'!F40*days_per_year*Cap_poultry -> 1412272800 | J25: 2023 | K25: Industry average for capacity use. | L25: See Table 5.5 to 5.8 on Tab 5.1-5.16. Company data; Company reports and presentations
A26: Main | B26: JBS | C26: BR | D26: Chicken | E26: Western Europe | F26: UK | G26: n/a | H26: est. daily cap. | I26: ='Additional company data'!E40*days_per_year*Cap_poultry*'Additional company data'!S39/SUM('Additional company data'!S38:S39) -> 3.9430978e+08 | J26: 2023 | K26: Industry average for capacity use; disaggregating cross-regional production based on brand distribution. | L26: See Table 5.5 to 5.8 on Tab 5.1-5.16. Company data; Company reports and presentations
A27: Main | B27: Tyson | C27: US | D27: Chicken | E27: North America | F27: US | G27: ='Additional company data'!C47*52*'Additional company data'!D47*'Additional company data'!E47 -> 1.7333613e+09 | I27: =G27 -> 1.7333613e+09 | J27: 2023 | K27: Company-reported capacity use; disaggregating cross-regional production based on facility distribution. | L27: See Table 5.9 on Tab 5.1-5.16. Company data; Tyson 2023 Annual Report on Form 10-K, Item 2 | M27: https://s203.q4cdn.com/483587180/files/doc_financials/annual/2023/tsn-2023-10k-final.pdf
A28: Main | B28: Tyson | C28: US | D28: Chicken | E28: East Asia and Southeast Asia | F28: multiple | G28: ='Additional company data'!C47*52*'Additional company data'!D47*'Additional company data'!G47 -> 2.0883871e+08 | I28: =G28 -> 2.0883871e+08 | J28: 2023 | K28: Company-reported capacity use; disaggregating cross-regional production based on facility distribution. | L28: See Table 5.9 on Tab 5.1-5.16. Company data; Tyson 2023 Annual Report on Form 10-K, Item 2 | M28: https://s203.q4cdn.com/483587180/files/doc_financials/annual/2023/tsn-2023-10k-final.pdf
A29: Main | B29: BRF | C29: BR | D29: Chicken | E29: South America | F29: BR | G29: n/a | H29: 35.8 mln weekly | I29: =35800000*52*Cap_poultry -> 1612145600 | J29: 2023 | K29: Industry average for capacity use. | L29: BRF (2024), Form 20-F Annual Report 2023, p. 63 | M29: https://api.mziq.com/mzfilemanager/v2/d/4d44a134-36cc-4fea-b520-393c4aceabb2/29f6dbb8-4762-9fbf-0ea9-448dbb27a181?origin=1
A30: Main | B30: Wen's Food Group | C30: CN | D30: Chicken | E30: East Asia and Southeast Asia | F30: CN | G30: ='Additional company data'!F88 -> 1183000000 | I30: =G30 -> 1183000000 | J30: 2023 | L30: Poultry International (2024), Top world broiler and egg rankings 2024, pp. 8-10 | M30: https://www.poultryinternational-digital.com/poultryinternational/october_november_2024/MobilePagedArticle.action?articleId=2013060#articleId2013060
A31: Main | B31: Cargill | C31: US | D31: Chicken | E31: North America | F31: US | G31: ='Additional company data'!F89*50% -> 535600000 | I31: =G31 -> 535600000 | J31: 2023 | K31: Wayne Sanderson is Cargill's 50/50 JV in NA with Continental Grain. Assigned 50% to each. | L31: Poultry International (2024), Top world broiler and egg rankings 2024, pp. 8-10 | M31: https://www.poultryinternational-digital.com/poultryinternational/october_november_2024/MobilePagedArticle.action?articleId=2013060#articleId2013060
A32: Main | B32: Cargill | C32: US | D32: Chicken | E32: Latin America and the Caribbean | F32: multiple | G32: ='Additional company data'!F102 -> 269000000 | I32: =G32 -> 269000000 | J32: 2023 | K32: Cargill Proteína Latinoamérico. | L32: Poultry International (2024), Top world broiler and egg rankings 2024, pp. 8-10 | M32: https://www.poultryinternational-digital.com/poultryinternational/october_november_2024/MobilePagedArticle.action?articleId=2013060#articleId2013060
A33: Main | B33: Cargill | C33: US | D33: Chicken | E33: East Asia and Southeast Asia | F33: multiple | G33: ='Additional company data'!F103 -> 180000000 | I33: =G33 -> 180000000 | J33: 2023 | K33: Cargill Meats Asia; China operation has been sold. | L33: Poultry International (2024), Top world broiler and egg rankings 2024, pp. 8-10 | M33: https://www.poultryinternational-digital.com/poultryinternational/october_november_2024/MobilePagedArticle.action?articleId=2013060#articleId2013060
A34: Main | B34: Cargill | C34: US | D34: Chicken | E34: Europe | F34: UK | G34: ='Additional company data'!F104 -> 144000000 | I34: =G34 -> 144000000 | J34: 2023 | K34: Cargill Meats Europe. | L34: Poultry International (2024), Top world broiler and egg rankings 2024, pp. 8-10 | M34: https://www.poultryinternational-digital.com/poultryinternational/october_november_2024/MobilePagedArticle.action?articleId=2013060#articleId2013060
A35: Main | B35: Japfa | C35: SG | D35: Chicken | E35: East Asia and Southeast Asia | F35: multiple | G35: ='Additional company data'!F90 -> 981000000 | I35: =G35 -> 981000000 | J35: 2023 | L35: Poultry International (2024), Top world broiler and egg rankings 2024, pp. 8-10 | M35: https://www.poultryinternational-digital.com/poultryinternational/october_november_2024/MobilePagedArticle.action?articleId=2013060#articleId2013060
A36: Main | B36: Wellhope Agritech | C36: CN | D36: Chicken | E36: East Asia and Southeast Asia | F36: CN | G36: ='Additional company data'!F91 -> 810000000 | I36: =G36 -> 810000000 | J36: 2023 | L36: Poultry International (2024), Top world broiler and egg rankings 2024, pp. 8-10 | M36: https://www.poultryinternational-digital.com/poultryinternational/october_november_2024/MobilePagedArticle.action?articleId=2013060#articleId2013060
A37: Main | B37: Charoen Pokphand | C37: TH | D37: Chicken | E37: East Asia and Southeast Asia | F37: multiple | G37: =SUM('Additional company data'!F93:F94) -> 685000000 | I37: =G37 -> 685000000 | J37: 2023 | L37: Poultry International (2024), Top world broiler and egg rankings 2024, pp. 8-10 | M37: https://www.poultryinternational-digital.com/poultryinternational/october_november_2024/MobilePagedArticle.action?articleId=2013060#articleId2013060
A38: Main | B38: Charoen Pokphand | C38: TH | D38: Chicken | E38: Russian Federation | F38: RU | G38: =(408700-263400)*1000/'Additional data sources'!G13 -> 66347032 | I38: =G38 -> 66347032 | J38: 2022 | K38: CP Foods produces pork and poultry in Russia. Information on combined 2022 production minus pork production used to estimate heads of chicken processed. | L38: Vet and Life (2023, February 8), Top 20 Russian pork producers compiled [Russian]; Agromics (2024, October 30), Rating of the top-25 largest meat producers in the Russian Federation in 2023. | M38: https://vetandlife.ru/sobytiya/sostavlen-top-20-rossijskih-proizvoditelej-svininy/; https://agromics.ru/novosti/reyting-myaso/
A39: Main | B39: Fuijan Sunner Development | C39: CN | D39: Chicken | E39: East Asia and Southeast Asia | F39: CN | G39: ='Additional company data'!F95 -> 680000000 | I39: =G39 -> 680000000 | J39: 2023 | L39: Poultry International (2024), Top world broiler and egg rankings 2024, pp. 8-10 | M39: https://www.poultryinternational-digital.com/poultryinternational/october_november_2024/MobilePagedArticle.action?articleId=2013060#articleId2013060
A40: Main | B40: Koch Foods | C40: US | D40: Chicken | E40: North America | F40: US | G40: ='Additional company data'!F96 -> 670000000 | I40: =G40 -> 670000000 | J40: 2023 | L40: Poultry International (2024), Top world broiler and egg rankings 2024, pp. 8-10 | M40: https://www.poultryinternational-digital.com/poultryinternational/october_november_2024/MobilePagedArticle.action?articleId=2013060#articleId2013060
A41: Main | B41: Arab Company for Livestock Development (ACOLID) | C41: AE | D41: Chicken | E41: Near East and North Africa | F41: multiple | G41: ='Additional company data'!F97 -> 662200000 | I41: =G41 -> 662200000 | J41: 2023 | L41: Poultry International (2024), Top world broiler and egg rankings 2024, pp. 8-10 | M41: https://www.poultryinternational-digital.com/poultryinternational/october_november_2024/MobilePagedArticle.action?articleId=2013060#articleId2013060
...

Sheet Additional company data
A3: Danone: | B3: Table 5.1 and 5.2 | C3: EXHAUSTIVE 2021 EXTRAFINANCIAL DATA page 12
B4: PROCUREMENT DATA | F4: 2020 | G4: 2021 | H4: 2021 adjusted* | I4: 2022
B5: Relationship with milk producers: | H5: *adjusted to make percentages add exactly to 100% instead of 99%
B6: Number of farms from which Danone sources directly or indirectly milk | E6: Number of farms | F6: 50000 | G6: 59000 | I6: 58000
B7: Number of these farms which are smallholders | E7: % | F7: 0.8 | G7: 0.94 | I7: 0.94
B8: Tonnage of milk directly sourced by Danone worldwide | E8: ktons | F8: 5100 | G8: 5567 | I8: 5100
B9: (a)For 2020 and before, smallholders farms were defined as “less than 10 cows”. From 2021 onwards, it is defined as “less than 25 cows”
B10: Main sourcing regions:
B11: Europe | E11: % | F11: 0.29 | G11: 0.26 | H11: =G11*1/SUM($G$11:$G$15) -> 0.26262626 | I11: 0.26
B12: CIS | E12: % | F12: 0.24 | G12: 0.23 | H12: =G12*1/SUM($G$11:$G$15) -> 0.23232323 | I12: 0.23
B13: North America | E13: % | F13: 0.21 | G13: 0.29 | H13: =G13*1/SUM($G$11:$G$15) -> 0.29292929 | I13: 0.29
B14: Latin America | F14: 0.11 | G14: 0.1 | H14: =G14*1/SUM($G$11:$G$15) -> 0.1010101 | I14: 0.11
B15: Other regions | E15: % | F15: 0.15 | G15: 0.11 | H15: =G15*1/SUM($G$11:$G$15) -> 0.11111111 | I15: 0.11
B16: Percentage of total milk collected directly by Danone coming from producers working under CPM contract (a) | E16: % | F16: 0.29 | G16: 0.26 | I16: 0.23
B17: Percentage of milk collected directly by Danone in EU coming from producers working under CPM contract | E17: % | F17: 0.43 | G17: 0.36 | I17: 0.44
B18: Percentage of milk collected directly by Danone in the U.S coming from producers working under CPM contract | E18: % | F18: 0.55 | G18: 0.54 | I18: 0.54
B19: Number of entities having deployed the Cool Farm Tool | E19: Number of entities | F19: 14 | G19: 15 | I19: 15
B20: Number of entities having implemented the Animal Welfare tool | E20: Number of entities | F20: 14 | G20: 15 | I20: 15
A23: WH Group: | B23: Table 5.3 and 5.4 | C23: WH Group (2023) Annual Report 2023
B24: Pigs
B25: Head slaughtered 2023 (million) | D25: 49.169
D27: Capacity (million heads) | E27: Capacity utilisation
B28: China | D28: 25.05 | E28: 0.509
B29: U.S. | D29: 30.09 | E29: 0.956
B30: Europe | D30: 5.72 | E30: 1.059
B32: Correction factor* | D32: =D25/SUMPRODUCT(D28:D30,E28:E30) -> 1.0335274 | F32: *Total reported animals processed/number implied by capacity and utilisation)
A35: JBS: | B35: Table 5.5 | C35: JBS Institutional Presentation including 4Q23 and 2023 Results | H35: Table 5.6 | I35: JBS Institutional Presentation including 4Q23 and 2023 Results | N35: JBS (2024) About our company | Q35: Table 5.7 | R35: Pilgrim's Pride facilities and locations (https://sustainability.pilgrims.com/chapters/who-we-are/facilities-and-locations/) | U35: Table 5.8 | V35: 10-K - PILGRIMS PRIDE CORP 2023, Item 2
B36: Used to estimate total meat production | H36: Used to disaggregate meat production by region | Q36: Used to disaggregate meat production by region | U36: Used to identify capacity and capacity utilisation for Pilgrim's Pride poultry and pork
B37: Daily capacity | C37: JBS Brazil | D37: JBS USA | E37: Pilgrim's Pride | F37: Seara | H37: Daily capacity | I37: JBS USA beef | J37: JBS USA pork | K37: JBS Canada | L37: JBS Australia | N37: Weekly capacity | O37: Pilgrim's Pride | Q37: Fresh chicken processing plants | S37: Pilgrim's Pride | W37: Daily capacity | X37: Capacity utilisation
B38: Cattle | C38: 33545 | D38: 42196 | E38: - | F38: - | H38: Cattle | I38: 32598 | L38: 9598 | N38: Cattle | Q38: North America | S38: 32 | U38: Chickens | W38: 8400000 | X38: 0.922
B39: Pigs | C39: - | D39: 92600 | E39: 8500 | F39: 30400 | H39: Pigs | J39: 92600 | L39: 10660 | N39: Pigs | O39: 45000 | Q39: Western Europe | S39: 7 | U39: Pigs | W39: 7425 | X39: 0.908
B40: Chicken | C40: - | D40: - | E40: 8400000 | F40: 5400000 | H40: Chicken | N40: Chicken | O40: 44900000
A43: Tyson | B43: Table 5.9 | C43: Tyson (2023) 10-k form, Nov 2023 Item 2 (utilization rates taken from Tyson (2022) 10-k form, as those are missing from the 2023 edition
C44: Weekly slaughter capacity | D44: Capacity utilisation | E44: Facilities in USA | F44: Facilities in Oceania | G44: Facilities in East Asia
B45: Cattle | C45: 155000 | D45: 0.79 | E45: =13/14 -> 0.92857143 | F45: =1/14 -> 0.071428571 | G45: -
B46: Pigs | C46: 471000 | D46: 0.84 | E46: 1 | F46: - | G46: -
B47: Chicken | C47: 45000000 | D47: 0.83 | E47: =166/186 -> 0.89247312 | F47: - | G47: =20/186 -> 0.10752688
A50: Gruppo Cremonini | B50: Table 5.10 | C50: Company communication; Inalca CSR report
C51: Volume of meat processed (t) | D51: Carcass weight (t) | E51: Live weight (t) | F51: No of animals (heads)
B52: Cattle | C52: =205513+233738 -> 439251 | D52: =C52/'Additional data sources'!D4 -> 585668 | E52: =D52/'Additional data sources'!H$17*100 -> 989861.41 | F52: =E52/'Additional data sources'!H$11*1000 -> 1864145.8
...

Sheet Additional data sources
B2: Table 7.1: Bone free meat weight, kg per kg carcass
C3: Species | D3: Bone free meat (fraction)
C4: Cattle | D4: 0.75
C5: Pigs | D5: 0.65
C6: Chicken | D6: 0.75
C7: Source: GLEAM 2.0 User Guide Table 9.1
B9: Table 7.2: Slaughter weight, kg per animal
C10: Species | D10: Production system | E10: Source | F10: North America | G10: Russian Federation | H10: Western Europe | I10: Eastern Europe | J10: Near East and North Africa | K10: East Asia and Southeast Asia | L10: Oceania | M10: South Asia | N10: Latin America and the Caribbean | O10: Sub-Saharan Africa | P10: Note
C11: Cattle | D11: Mixed or Grassland | E11: GLEAM Supplement S1 Table 2.4-2.7 | F11: 598.16667 | G11: 530 | H11: 531 | I11: 530 | J11: 341 | K11: 350.83333 | L11: 382 | M11: 133.66667 | N11: 449.5 | O11: 247 | P11: Average on 3:2:1 slaughter assumption steers:heifers:culled cows
C12: Pigs | D12: Industrial | E12: GLEAM Supplement S1 Table 2.16 | F12: 115 | G12: 116 | H12: 116 | I12: 116 | J12: 111 | K12: 113 | L12: 73 | M12: 115 | N12: 115 | O12: 116 | P12: -
C13: Chicken | D13: Broiler | E13: GLEAM Supplement S1 Table 2.21 | F13: 2.67 | G13: 2.19 | H13: 2.33 | I13: 2.19 | J13: 1.87 | K13: 1.89 | L13: 2.28 | M13: 2 | N13: 2.47 | O13: 1.5 | P13: -
B15: Table 7.3: Dressing percentage
C16: Species | D16: Production system | E16: Source | F16: North America | G16: Russian Federation | H16: Western Europe | I16: Eastern Europe | J16: Near East and North Africa | K16: East Asia and Southeast Asia | L16: Oceania | M16: South Asia | N16: Latin America and the Caribbean | O16: Sub-Saharan Africa | P16: Note
C17: Cattle | D17: Average | E17: GLEAM Supplement S1 Table 9.2 | F17: 59.166667 | G17: 59.166667 | H17: 59.166667 | I17: 59.166667 | J17: 54.166667 | K17: 54.166667 | L17: 54.166667 | M17: 54.166667 | N17: 54.166667 | O17: 47 | P17: Average on 3:2:1 slaughter assumption steers:heifers:culled cows
C18: Pigs | D18: Industrial | E18: GLEAM Supplement S1 Table 9.2 | F18: 75 | G18: 75 | H18: 75 | I18: 75 | J18: 75 | K18: 75 | L18: 75 | M18: 75 | N18: 75 | O18: 75 | P18: Western Europe value is average of reported country-specific values
C19: Chicken | D19: Broiler | E19: GLEAM Supplement S1 Table 9.2 | F19: 68 | G19: 70 | H19: 67 | I19: 70 | J19: 67 | K19: 63 | L19: 66 | M19: 68 | N19: 88 | O19: 65 | P19: -
B22: Table 7.4: Capacity utilisation assumptions
C23: Days operational per year | D23: =365-52-11 -> 302
C25: Species | D25: Assumed utilisation rate
C26: Cattle | D26: 0.91
C27: Pigs | D27: 0.96
C28: Poultry | D28: 0.866
