Workbook

Sheet Overview
A1: Tab Name | B1: Description
A2: Summary for Figures | B2: Summary of the relative processing and relative impacts of the TNCs to the world for use in the figures
A3: Relative Processing | B3: Processing of animal products relative to world in weight
A4: Relative Impacts | B4: Environmental impacts of TNCs' animal products relative to world
A5: Global Impacts | B5: Calculated global impacts across all animal products from FABIO
A6: All TNC Impacts | B6: Combination of the following four tabs
A7: Bovine Meat | B7: Directly from Results_all_impacts.xlsx and including 3 significant digits rounding
A8: Poultry Meat | B8: Directly from Results_all_impacts.xlsx and including 3 significant digits rounding
A9: Pigmeat | B9: Directly from Results_all_impacts.xlsx and including 3 significant digits rounding
A10: Milk - Excluding Butter | B10: Directly from Results_all_impacts.xlsx and including 3 significant digits rounding

Sheet Summary for Figures
A1: Animal product | B1: Impact or count | C1: Category | D1: Amount | E1: Amount (rounded)
A2: Beef | B2: Slaughtered (million heads) | C2: Companies | D2: ='Relative Processing'!B5/1000000 -> 54.387899 | E2: =IF(AND(D2>1, D2<>""), ROUND(D2, 3 - LEN(INT(ABS(D2)))), D2) -> 54.4
A3: Beef | B3: Slaughtered (million heads) | C3: Global | D3: ='Relative Processing'!C5/1000000 -> 315 | E3: =IF(AND(D3>1, D3<>""), ROUND(D3, 3 - LEN(INT(ABS(D3)))), D3) -> 315
A4: Beef | B4: Slaughtered (million heads) | C4: Percentage | D4: =D2/D3 -> 0.17266 | E4: =IF(AND(D4>1, D4<>""), ROUND(D4, 3 - LEN(INT(ABS(D4)))), D4) -> 0.17266
A5: Beef | B5: Land use (Mha) | C5: Companies | D5: ='Relative Impacts'!D6/1000 -> 370.002 | E5: =IF(AND(D5>1, D5<>""), ROUND(D5, 3 - LEN(INT(ABS(D5)))), D5) -> 370
A6: Beef | B6: Land use (Mha) | C6: Global | D6: ='Relative Impacts'!K6/1000 -> 1282.069 | E6: =IF(AND(D6>1, D6<>""), ROUND(D6, 3 - LEN(INT(ABS(D6)))), D6) -> 1280
A7: Beef | B7: Land use (Mha) | C7: Percentage | D7: =D5/D6 -> 0.28859756 | E7: =IF(AND(D7>1, D7<>""), ROUND(D7, 3 - LEN(INT(ABS(D7)))), D7) -> 0.28859756
A8: Beef | B8: Blue and green water use (km³) | C8: Companies | D8: ='Relative Impacts'!D5/1000000 -> 373.48559 | E8: =IF(AND(D8>1, D8<>""), ROUND(D8, 3 - LEN(INT(ABS(D8)))), D8) -> 373
A9: Beef | B9: Blue and green water use (km³) | C9: Global | D9: ='Relative Impacts'!K5/1000000 -> 1496.5023 | E9: =IF(AND(D9>1, D9<>""), ROUND(D9, 3 - LEN(INT(ABS(D9)))), D9) -> 1500
A10: Beef | B10: Blue and green water use (km³) | C10: Percentage | D10: =D8/D9 -> 0.24957235 | E10: =IF(AND(D10>1, D10<>""), ROUND(D10, 3 - LEN(INT(ABS(D10)))), D10) -> 0.24957235
A11: Beef | B11: Nitrogen application (kt) | C11: Companies | D11: ='Relative Impacts'!D7/1000 -> 1774.312 | E11: =IF(AND(D11>1, D11<>""), ROUND(D11, 3 - LEN(INT(ABS(D11)))), D11) -> 1770
A12: Beef | B12: Nitrogen application (kt) | C12: Global | D12: ='Relative Impacts'!K7/1000 -> 5856.9232 | E12: =IF(AND(D12>1, D12<>""), ROUND(D12, 3 - LEN(INT(ABS(D12)))), D12) -> 5860
A13: Beef | B13: Nitrogen application (kt) | C13: Percentage | D13: =D11/D12 -> 0.30294268 | E13: =IF(AND(D13>1, D13<>""), ROUND(D13, 3 - LEN(INT(ABS(D13)))), D13) -> 0.30294268
A14: Poultry | B14: Slaughtered (million heads) | C14: Companies | D14: ='Relative Processing'!B3/1000000 -> 17551.258 | E14: =IF(AND(D14>1, D14<>""), ROUND(D14, 3 - LEN(INT(ABS(D14)))), D14) -> 17600
A15: Poultry | B15: Slaughtered (million heads) | C15: Global | D15: ='Relative Processing'!C3/1000000 -> 75700 | E15: =IF(AND(D15>1, D15<>""), ROUND(D15, 3 - LEN(INT(ABS(D15)))), D15) -> 75700
A16: Poultry | B16: Slaughtered (million heads) | C16: Percentage | D16: =D14/D15 -> 0.23185281 | E16: =IF(AND(D16>1, D16<>""), ROUND(D16, 3 - LEN(INT(ABS(D16)))), D16) -> 0.23185281
A17: Poultry | B17: Land use (Mha) | C17: Companies | D17: ='Relative Impacts'!D21/1000 -> 16.836 | E17: =IF(AND(D17>1, D17<>""), ROUND(D17, 3 - LEN(INT(ABS(D17)))), D17) -> 16.8
A18: Poultry | B18: Land use (Mha) | C18: Global | D18: ='Relative Impacts'!K21/1000 -> 70.313746 | E18: =IF(AND(D18>1, D18<>""), ROUND(D18, 3 - LEN(INT(ABS(D18)))), D18) -> 70.3
A19: Poultry | B19: Land use (Mha) | C19: Percentage | D19: =D17/D18 -> 0.23944109 | E19: =IF(AND(D19>1, D19<>""), ROUND(D19, 3 - LEN(INT(ABS(D19)))), D19) -> 0.23944109
A20: Poultry | B20: Blue and green water use (km³) | C20: Companies | D20: ='Relative Impacts'!D20/1000000 -> 97.794796 | E20: =IF(AND(D20>1, D20<>""), ROUND(D20, 3 - LEN(INT(ABS(D20)))), D20) -> 97.8
A21: Poultry | B21: Blue and green water use (km³) | C21: Global | D21: ='Relative Impacts'!K20/1000000 -> 405.32238 | E21: =IF(AND(D21>1, D21<>""), ROUND(D21, 3 - LEN(INT(ABS(D21)))), D21) -> 405
A22: Poultry | B22: Blue and green water use (km³) | C22: Percentage | D22: =D20/D21 -> 0.24127658 | E22: =IF(AND(D22>1, D22<>""), ROUND(D22, 3 - LEN(INT(ABS(D22)))), D22) -> 0.24127658
A23: Poultry | B23: Nitrogen application (kt) | C23: Companies | D23: ='Relative Impacts'!D22/1000 -> 931.799 | E23: =IF(AND(D23>1, D23<>""), ROUND(D23, 3 - LEN(INT(ABS(D23)))), D23) -> 932
A24: Poultry | B24: Nitrogen application (kt) | C24: Global | D24: ='Relative Impacts'!K22/1000 -> 3342.6078 | E24: =IF(AND(D24>1, D24<>""), ROUND(D24, 3 - LEN(INT(ABS(D24)))), D24) -> 3340
A25: Poultry | B25: Nitrogen application (kt) | C25: Percentage | D25: =D23/D24 -> 0.27876408 | E25: =IF(AND(D25>1, D25<>""), ROUND(D25, 3 - LEN(INT(ABS(D25)))), D25) -> 0.27876408
A26: Pork | B26: Slaughtered (million heads) | C26: Companies | D26: ='Relative Processing'!B4/1000000 -> 267.74621 | E26: =IF(AND(D26>1, D26<>""), ROUND(D26, 3 - LEN(INT(ABS(D26)))), D26) -> 268
A27: Pork | B27: Slaughtered (million heads) | C27: Global | D27: ='Relative Processing'!C4/1000000 -> 1480 | E27: =IF(AND(D27>1, D27<>""), ROUND(D27, 3 - LEN(INT(ABS(D27)))), D27) -> 1480
A28: Pork | B28: Slaughtered (million heads) | C28: Percentage | D28: =D26/D27 -> 0.1809096 | E28: =IF(AND(D28>1, D28<>""), ROUND(D28, 3 - LEN(INT(ABS(D28)))), D28) -> 0.1809096
A29: Pork | B29: Land use (Mha) | C29: Companies | D29: ='Relative Impacts'!D16/1000 -> 34.751 | E29: =IF(AND(D29>1, D29<>""), ROUND(D29, 3 - LEN(INT(ABS(D29)))), D29) -> 34.8
A30: Pork | B30: Land use (Mha) | C30: Global | D30: ='Relative Impacts'!K16/1000 -> 143.15381 | E30: =IF(AND(D30>1, D30<>""), ROUND(D30, 3 - LEN(INT(ABS(D30)))), D30) -> 143
A31: Pork | B31: Land use (Mha) | C31: Percentage | D31: =D29/D30 -> 0.24275289 | E31: =IF(AND(D31>1, D31<>""), ROUND(D31, 3 - LEN(INT(ABS(D31)))), D31) -> 0.24275289
A32: Pork | B32: Blue and green water use (km³) | C32: Companies | D32: ='Relative Impacts'!D15/1000000 -> 184.74237 | E32: =IF(AND(D32>1, D32<>""), ROUND(D32, 3 - LEN(INT(ABS(D32)))), D32) -> 185
A33: Pork | B33: Blue and green water use (km³) | C33: Global | D33: ='Relative Impacts'!K15/1000000 -> 789.06741 | E33: =IF(AND(D33>1, D33<>""), ROUND(D33, 3 - LEN(INT(ABS(D33)))), D33) -> 789
A34: Pork | B34: Blue and green water use (km³) | C34: Percentage | D34: =D32/D33 -> 0.23412749 | E34: =IF(AND(D34>1, D34<>""), ROUND(D34, 3 - LEN(INT(ABS(D34)))), D34) -> 0.23412749
A35: Pork | B35: Nitrogen application (kt) | C35: Companies | D35: ='Relative Impacts'!D17/1000 -> 2263.821 | E35: =IF(AND(D35>1, D35<>""), ROUND(D35, 3 - LEN(INT(ABS(D35)))), D35) -> 2260
A36: Pork | B36: Nitrogen application (kt) | C36: Global | D36: ='Relative Impacts'!K17/1000 -> 8767.8344 | E36: =IF(AND(D36>1, D36<>""), ROUND(D36, 3 - LEN(INT(ABS(D36)))), D36) -> 8770
A37: Pork | B37: Nitrogen application (kt) | C37: Percentage | D37: =D35/D36 -> 0.25819614 | E37: =IF(AND(D37>1, D37<>""), ROUND(D37, 3 - LEN(INT(ABS(D37)))), D37) -> 0.25819614
A38: Dairy | B38: Processed (Mt) | C38: Companies | D38: ='Relative Processing'!B6/1000000 -> 190.2 | E38: =IF(AND(D38>1, D38<>""), ROUND(D38, 3 - LEN(INT(ABS(D38)))), D38) -> 190
A39: Dairy | B39: Processed (Mt) | C39: Global | D39: ='Relative Processing'!C6/1000000 -> 462 | E39: =IF(AND(D39>1, D39<>""), ROUND(D39, 3 - LEN(INT(ABS(D39)))), D39) -> 462
A40: Dairy | B40: Processed (Mt) | C40: Percentage | D40: =D38/D39 -> 0.41168831 | E40: =IF(AND(D40>1, D40<>""), ROUND(D40, 3 - LEN(INT(ABS(D40)))), D40) -> 0.41168831
...

Sheet Relative Processing
A1: Production of animal products relative to world in weight
B2: Profundo data | C2: FAOStat global total
A3: chickens | B3: 17551257788 | C3: 75700000000 | D3: =B3/C3 -> 0.23185281
A4: pigs | B4: 267746214 | C4: 1480000000 | D4: =B4/C4 -> 0.1809096
A5: cattle | B5: 54387899 | C5: 315000000 | D5: =B5/C5 -> 0.17266
A6: dairy | B6: 190200000 | C6: 462000000 | D6: =B6/C6 -> 0.41168831

Sheet Relative Impacts
A1: All TNC Impacts | G1: Global Impacts | J1: All TNC Impacts Relative to Global Impacts (Combined Blue & Green Water)
A2: Pivot Table | C2: Combined blue and green water impacts | G2: Pivot Table | J2: Combined blue and green water impacts
A3: Row Labels | B3: Sum of Footprint amount | C3: Animal product and impact type | D3: Amount | E3: Unit | G3: Row Labels | H3: Sum of Footprint | J3: Animal product and impact type | K3: Amount | L3: Relative Percentage | M3: Unit
A4: Bovine Meat | B4: 375629905 | C4: =A4 -> Bovine Meat | G4: Bovine Meat | H4: 1.5036413e+12 | J4: =G4 -> Bovine Meat
A5: Blue water | B5: 16293926 | C5: Blue and green water footprint | D5: =B5+B6 -> 373485591 | E5: 1000 m³ | G5: Blue Water Footprint (m³) | H5: 7.3341994e+10 | J5: =C5 -> Blue and green water footprint | K5: =(H5+H6)/1000 -> 1.4965023e+09 | L5: =D5/K5 -> 0.24957235 | M5: 1000 m³
A6: Green water | B6: 357191665 | C6: =A7 -> Land use | D6: =B7 -> 370002 | E6: kha | G6: Green Water Footprint (m³) | H6: 1.4231603e+12 | J6: =C6 -> Land use | K6: =H7/1000 -> 1282069 | L6: =D6/K6 -> 0.28859756 | M6: kha
A7: Land use | B7: 370002 | C7: =A8 -> Nitrogen application | D7: =B8 -> 1774312 | E7: t | G7: Land Use Footprint (ha) | H7: 1.282069e+09 | J7: =C7 -> Nitrogen application | K7: =H8/1000 -> 5856923.2 | L7: =D7/K7 -> 0.30294268 | M7: t
A8: Nitrogen application | B8: 1774312 | G8: Nitrogen Application (kg) | H8: 5.8569232e+09
A9: Milk - Excluding Butter | B9: 160847325 | C9: =A9 -> Milk - Excluding Butter | G9: Milk - Excluding Butter | H9: 8.9852286e+11 | J9: =C9 -> Milk - Excluding Butter
A10: Blue water | B10: 7955661 | C10: Blue and green water footprint | D10: =B10+B11 -> 159011302 | E10: 1000 m³ | G10: Blue Water Footprint (m³) | H10: 5.1749014e+10 | J10: =C10 -> Blue and green water footprint | K10: =(H10+H11)/1000 -> 8.9218598e+08 | L10: =D10/K10 -> 0.17822663 | M10: 1000 m³
A11: Green water | B11: 151055641 | C11: =A12 -> Land use | D11: =B12 -> 78758 | E11: kha | G11: Green Water Footprint (m³) | H11: 8.4043696e+11 | J11: =C11 -> Land use | K11: =H12/1000 -> 463991.16 | L11: =D11/K11 -> 0.1697403 | M11: kha
A12: Land use | B12: 78758 | C12: =A13 -> Nitrogen application | D12: =B13 -> 1757265 | E12: t | G12: Land Use Footprint (ha) | H12: 4.6399116e+08 | J12: =C12 -> Nitrogen application | K12: =H13/1000 -> 5872894 | L12: =D12/K12 -> 0.2992162 | M12: t
A13: Nitrogen application | B13: 1757265 | G13: Nitrogen Application (kg) | H13: 5.872894e+09
A14: Pigmeat | B14: 187040945 | C14: =A14 -> Pigmeat | G14: Pigmeat | H14: 7.979784e+11 | J14: =C14 -> Pigmeat
A15: Blue water | B15: 12217402 | C15: Blue and green water footprint | D15: =B15+B16 -> 184742373 | E15: 1000 m³ | G15: Blue Water Footprint (m³) | H15: 5.1212134e+10 | J15: =C15 -> Blue and green water footprint | K15: =(H15+H16)/1000 -> 7.8906741e+08 | L15: =D15/K15 -> 0.23412749 | M15: 1000 m³
A16: Green water | B16: 172524971 | C16: =A17 -> Land use | D16: =B17 -> 34751 | E16: kha | G16: Green Water Footprint (m³) | H16: 7.3785527e+11 | J16: =C16 -> Land use | K16: =H17/1000 -> 143153.81 | L16: =D16/K16 -> 0.24275289 | M16: kha
A17: Land use | B17: 34751 | C17: =A18 -> Nitrogen application | D17: =B18 -> 2263821 | E17: t | G17: Land Use Footprint (ha) | H17: 1.4315381e+08 | J17: =C17 -> Nitrogen application | K17: =H18/1000 -> 8767834.4 | L17: =D17/K17 -> 0.25819614 | M17: t
A18: Nitrogen application | B18: 2263821 | G18: Nitrogen Application (kg) | H18: 8.7678344e+09
A19: Poultry Meat | B19: 98743431 | C19: =A19 -> Poultry Meat | G19: Poultry Meat | H19: 4.087353e+11 | J19: =C19 -> Poultry Meat
A20: Blue water | B20: 6419016 | C20: Blue and green water footprint | D20: =B20+B21 -> 97794796 | E20: 1000 m³ | G20: Blue Water Footprint (m³) | H20: 3.107729e+10 | J20: =C20 -> Blue and green water footprint | K20: =(H20+H21)/1000 -> 4.0532238e+08 | L20: =D20/K20 -> 0.24127658 | M20: 1000 m³
A21: Green water | B21: 91375780 | C21: =A22 -> Land use | D21: =B22 -> 16836 | E21: kha | G21: Green Water Footprint (m³) | H21: 3.7424509e+11 | J21: =C21 -> Land use | K21: =H22/1000 -> 70313.746 | L21: =D21/K21 -> 0.23944109 | M21: kha
A22: Land use | B22: 16836 | C22: =A23 -> Nitrogen application | D22: =B23 -> 931799 | E22: t | G22: Land Use Footprint (ha) | H22: 70313746 | J22: =C22 -> Nitrogen application | K22: =H23/1000 -> 3342607.8 | L22: =D22/K22 -> 0.27876408 | M22: t
A23: Nitrogen application | B23: 931799 | G23: Nitrogen Application (kg) | H23: 3.3426078e+09
A24: Grand Total | B24: 822261606 | G24: Grand Total | H24: 3.6088779e+12
A29: All TNC Impacts Relative to Global Impacts (Combined Blue & Green Water) Across Combined Animal Products
A30: Combined blue and green water impacts
A31: Impact type | B31: TNC impacts | C31: Global impacts | D31: Relative percentage | E31: Unit
A32: Blue and green water | B32: =D5+D10+D15+D20 -> 815034062 | C32: =K5+K10+K15+K20 -> 3.5830781e+09 | D32: =B32/C32 -> 0.22746757 | E32: 1000 m³
A33: Land use | B33: =D6+D11+D16+D21 -> 500347 | C33: =K6+K11+K16+K21 -> 1959527.7 | D33: =B33/C33 -> 0.2553406 | E33: kha
A34: Nitrogen application | B34: =D7+D12+D17+D22 -> 6727197 | C34: =K7+K12+K17+K22 -> 23840259 | D34: =B34/C34 -> 0.28217801 | E34: t

Sheet Global Impacts
B1: Footprint | C1: Animal_product | D1: Footprint_type
A2: 0 | B2: 70313746 | C2: Poultry Meat | D2: Land Use Footprint (ha)
A3: 1 | B3: 3.107729e+10 | C3: Poultry Meat | D3: Blue Water Footprint (m³)
A4: 2 | B4: 3.7424509e+11 | C4: Poultry Meat | D4: Green Water Footprint (m³)
A5: 3 | B5: 3.3426078e+09 | C5: Poultry Meat | D5: Nitrogen Application (kg)
A6: 4 | B6: 1.282069e+09 | C6: Bovine Meat | D6: Land Use Footprint (ha)
A7: 5 | B7: 7.3341994e+10 | C7: Bovine Meat | D7: Blue Water Footprint (m³)
A8: 6 | B8: 1.4231603e+12 | C8: Bovine Meat | D8: Green Water Footprint (m³)
A9: 7 | B9: 5.8569232e+09 | C9: Bovine Meat | D9: Nitrogen Application (kg)
A10: 8 | B10: 1.4315381e+08 | C10: Pigmeat | D10: Land Use Footprint (ha)
A11: 9 | B11: 5.1212134e+10 | C11: Pigmeat | D11: Blue Water Footprint (m³)
A12: 10 | B12: 7.3785527e+11 | C12: Pigmeat | D12: Green Water Footprint (m³)
A13: 11 | B13: 8.7678344e+09 | C13: Pigmeat | D13: Nitrogen Application (kg)
... A17: 15 | B17: 5.872894e+09 | C17: Milk - Excluding Butter | D17: Nitrogen Application (kg)

Sheet All TNC Impacts
A1: Company | B1: Land type | C1: Region | D1: Footprint amount | E1: Animal product | F1: Footprint | G1: Unit
A2: Bigard | B2: Grazing | C2: East Asia and Southeast Asia | D2: 0 | E2: Bovine Meat | F2: Land use | G2: (kha)
A3: Bigard | B3: Grazing | C3: Eastern Europe | D3: 18 | E3: Bovine Meat | F3: Land use | G3: (kha)
A4: Bigard | B4: Grazing | C4: Latin America and the Caribbean | D4: 0 | E4: Bovine Meat | F4: Land use | G4: (kha)
A5: Bigard | B5: Grazing | C5: Near East and North Africa | D5: 0 | E5: Bovine Meat | F5: Land use | G5: (kha)
A6: Bigard | B6: Grazing | C6: North America | D6: 0 | E6: Bovine Meat | F6: Land use | G6: (kha)
A7: Bigard | B7: Grazing | C7: Oceania | D7: 0 | E7: Bovine Meat | F7: Land use | G7: (kha)
A8: Bigard | B8: Grazing | C8: RoW | D8: 0 | E8: Bovine Meat | F8: Land use | G8: (kha)
A9: Bigard | B9: Grazing | C9: Russian Federation | D9: 0 | E9: Bovine Meat | F9: Land use | G9: (kha)
A10: Bigard | B10: Grazing | C10: South Asia | D10: 0 | E10: Bovine Meat | F10: Land use | G10: (kha)
A11: Bigard | B11: Grazing | C11: Sub-Saharan Africa | D11: 0 | E11: Bovine Meat | F11: Land use | G11: (kha)
A12: Bigard | B12: Grazing | C12: Western Europe | D12: 1605 | E12: Bovine Meat | F12: Land use | G12: (kha)
A13: Bigard | B13: Croplands | C13: East Asia and Southeast Asia | D13: 3 | E13: Bovine Meat | F13: Land use | G13: (kha)
... A6161: DMK | B6161: Croplands | C6161: Western Europe | D6161: 24921 | E6161: Milk - Excluding Butter | F6161: Nitrogen application | G6161: (t)

Sheet Bovine Meat
A1: Company | B1: Land type | C1: Region | D1: Footprint amount | E1: Animal product | F1: Footprint | G1: Unit | H1: Footprint amount (rounded)
A2: Bigard | B2: Grazing | C2: East Asia and Southeast Asia | D2: 0 | E2: Bovine Meat | F2: Land use | G2: (kha) | H2: =ROUND(D2, 3 - LEN(INT(ABS(D2)))) -> 0
A3: Bigard | B3: Grazing | C3: Eastern Europe | D3: 18 | E3: Bovine Meat | F3: Land use | G3: (kha) | H3: =ROUND(D3, 3 - LEN(INT(ABS(D3)))) -> 18
A4: Bigard | B4: Grazing | C4: Latin America and the Caribbean | D4: 0 | E4: Bovine Meat | F4: Land use | G4: (kha) | H4: =ROUND(D4, 3 - LEN(INT(ABS(D4)))) -> 0
A5: Bigard | B5: Grazing | C5: Near East and North Africa | D5: 0 | E5: Bovine Meat | F5: Land use | G5: (kha) | H5: =ROUND(D5, 3 - LEN(INT(ABS(D5)))) -> 0
A6: Bigard | B6: Grazing | C6: North America | D6: 0 | E6: Bovine Meat | F6: Land use | G6: (kha) | H6: =ROUND(D6, 3 - LEN(INT(ABS(D6)))) -> 0
A7: Bigard | B7: Grazing | C7: Oceania | D7: 0 | E7: Bovine Meat | F7: Land use | G7: (kha) | H7: =ROUND(D7, 3 - LEN(INT(ABS(D7)))) -> 0
A8: Bigard | B8: Grazing | C8: RoW | D8: 0 | E8: Bovine Meat | F8: Land use | G8: (kha) | H8: =ROUND(D8, 3 - LEN(INT(ABS(D8)))) -> 0
A9: Bigard | B9: Grazing | C9: Russian Federation | D9: 0 | E9: Bovine Meat | F9: Land use | G9: (kha) | H9: =ROUND(D9, 3 - LEN(INT(ABS(D9)))) -> 0
A10: Bigard | B10: Grazing | C10: South Asia | D10: 0 | E10: Bovine Meat | F10: Land use | G10: (kha) | H10: =ROUND(D10, 3 - LEN(INT(ABS(D10)))) -> 0
A11: Bigard | B11: Grazing | C11: Sub-Saharan Africa | D11: 0 | E11: Bovine Meat | F11: Land use | G11: (kha) | H11: =ROUND(D11, 3 - LEN(INT(ABS(D11)))) -> 0
A12: Bigard | B12: Grazing | C12: Western Europe | D12: 1605 | E12: Bovine Meat | F12: Land use | G12: (kha) | H12: =ROUND(D12, 3 - LEN(INT(ABS(D12)))) -> 1610
A13: Bigard | B13: Croplands | C13: East Asia and Southeast Asia | D13: 3 | E13: Bovine Meat | F13: Land use | G13: (kha) | H13: =ROUND(D13, 3 - LEN(INT(ABS(D13)))) -> 3
... A1145: Westfleisch | B1145: Croplands | C1145: Western Europe | D1145: 5808 | E1145: Bovine Meat | F1145: Nitrogen application | G1145: (t) | H1145: =ROUND(D1145, 3 - LEN(INT(ABS(D1145)))) -> 5810

Sheet Poultry Meat
A1: Company | B1: Land type | C1: Region | D1: Footprint amount | E1: Animal product | F1: Footprint | G1: Unit | H1: Footprint amount (rounded)
A2: Arab Company for Livestock Development (ACOLID) | B2: Grazing | C2: East Asia and Southeast Asia | D2: 0 | E2: Poultry Meat | F2: Land use | G2: (kha) | H2: =ROUND(D2, 3 - LEN(INT(ABS(D2)))) -> 0
A3: Arab Company for Livestock Development (ACOLID) | B3: Grazing | C3: Eastern Europe | D3: 0 | E3: Poultry Meat | F3: Land use | G3: (kha) | H3: =ROUND(D3, 3 - LEN(INT(ABS(D3)))) -> 0
A4: Arab Company for Livestock Development (ACOLID) | B4: Grazing | C4: Latin America and the Caribbean | D4: 0 | E4: Poultry Meat | F4: Land use | G4: (kha) | H4: =ROUND(D4, 3 - LEN(INT(ABS(D4)))) -> 0
A5: Arab Company for Livestock Development (ACOLID) | B5: Grazing | C5: Near East and North Africa | D5: 113 | E5: Poultry Meat | F5: Land use | G5: (kha) | H5: =ROUND(D5, 3 - LEN(INT(ABS(D5)))) -> 113
A6: Arab Company for Livestock Development (ACOLID) | B6: Grazing | C6: North America | D6: 0 | E6: Poultry Meat | F6: Land use | G6: (kha) | H6: =ROUND(D6, 3 - LEN(INT(ABS(D6)))) -> 0
A7: Arab Company for Livestock Development (ACOLID) | B7: Grazing | C7: Oceania | D7: 0 | E7: Poultry Meat | F7: Land use | G7: (kha) | H7: =ROUND(D7, 3 - LEN(INT(ABS(D7)))) -> 0
A8: Arab Company for Livestock Development (ACOLID) | B8: Grazing | C8: RoW | D8: 0 | E8: Poultry Meat | F8: Land use | G8: (kha) | H8: =ROUND(D8, 3 - LEN(INT(ABS(D8)))) -> 0
A9: Arab Company for Livestock Development (ACOLID) | B9: Grazing | C9: Russian Federation | D9: 0 | E9: Poultry Meat | F9: Land use | G9: (kha) | H9: =ROUND(D9, 3 - LEN(INT(ABS(D9)))) -> 0
A10: Arab Company for Livestock Development (ACOLID) | B10: Grazing | C10: South Asia | D10: 0 | E10: Poultry Meat | F10: Land use | G10: (kha) | H10: =ROUND(D10, 3 - LEN(INT(ABS(D10)))) -> 0
A11: Arab Company for Livestock Development (ACOLID) | B11: Grazing | C11: Sub-Saharan Africa | D11: 0 | E11: Poultry Meat | F11: Land use | G11: (kha) | H11: =ROUND(D11, 3 - LEN(INT(ABS(D11)))) -> 0
A12: Arab Company for Livestock Development (ACOLID) | B12: Grazing | C12: Western Europe | D12: 0 | E12: Poultry Meat | F12: Land use | G12: (kha) | H12: =ROUND(D12, 3 - LEN(INT(ABS(D12)))) -> 0
A13: Arab Company for Livestock Development (ACOLID) | B13: Croplands | C13: East Asia and Southeast Asia | D13: 5 | E13: Poultry Meat | F13: Land use | G13: (kha) | H13: =ROUND(D13, 3 - LEN(INT(ABS(D13)))) -> 5
... A1585: WH Group | B1585: Croplands | C1585: Western Europe | D1585: 443 | E1585: Poultry Meat | F1585: Nitrogen application | G1585: (t) | H1585: =ROUND(D1585, 3 - LEN(INT(ABS(D1585)))) -> 443

Sheet Pigmeat
A1: Company | B1: Land type | C1: Region | D1: Footprint amount | E1: Animal product | F1: Footprint | G1: Unit | H1: Footprint amount (rounded)
A2: Aurora Alimentos | B2: Grazing | C2: East Asia and Southeast Asia | D2: 0 | E2: Pigmeat | F2: Land use | G2: (kha) | H2: =ROUND(D2, 3 - LEN(INT(ABS(D2)))) -> 0
A3: Aurora Alimentos | B3: Grazing | C3: Eastern Europe | D3: 0 | E3: Pigmeat | F3: Land use | G3: (kha) | H3: =ROUND(D3, 3 - LEN(INT(ABS(D3)))) -> 0
A4: Aurora Alimentos | B4: Grazing | C4: Latin America and the Caribbean | D4: 71 | E4: Pigmeat | F4: Land use | G4: (kha) | H4: =ROUND(D4, 3 - LEN(INT(ABS(D4)))) -> 71
A5: Aurora Alimentos | B5: Grazing | C5: Near East and North Africa | D5: 0 | E5: Pigmeat | F5: Land use | G5: (kha) | H5: =ROUND(D5, 3 - LEN(INT(ABS(D5)))) -> 0
A6: Aurora Alimentos | B6: Grazing | C6: North America | D6: 0 | E6: Pigmeat | F6: Land use | G6: (kha) | H6: =ROUND(D6, 3 - LEN(INT(ABS(D6)))) -> 0
A7: Aurora Alimentos | B7: Grazing | C7: Oceania | D7: 0 | E7: Pigmeat | F7: Land use | G7: (kha) | H7: =ROUND(D7, 3 - LEN(INT(ABS(D7)))) -> 0
A8: Aurora Alimentos | B8: Grazing | C8: RoW | D8: 0 | E8: Pigmeat | F8: Land use | G8: (kha) | H8: =ROUND(D8, 3 - LEN(INT(ABS(D8)))) -> 0
A9: Aurora Alimentos | B9: Grazing | C9: Russian Federation | D9: 0 | E9: Pigmeat | F9: Land use | G9: (kha) | H9: =ROUND(D9, 3 - LEN(INT(ABS(D9)))) -> 0
A10: Aurora Alimentos | B10: Grazing | C10: South Asia | D10: 0 | E10: Pigmeat | F10: Land use | G10: (kha) | H10: =ROUND(D10, 3 - LEN(INT(ABS(D10)))) -> 0
A11: Aurora Alimentos | B11: Grazing | C11: Sub-Saharan Africa | D11: 0 | E11: Pigmeat | F11: Land use | G11: (kha) | H11: =ROUND(D11, 3 - LEN(INT(ABS(D11)))) -> 0
A12: Aurora Alimentos | B12: Grazing | C12: Western Europe | D12: 0 | E12: Pigmeat | F12: Land use | G12: (kha) | H12: =ROUND(D12, 3 - LEN(INT(ABS(D12)))) -> 0
A13: Aurora Alimentos | B13: Croplands | C13: East Asia and Southeast Asia | D13: 0 | E13: Pigmeat | F13: Land use | G13: (kha) | H13: =ROUND(D13, 3 - LEN(INT(ABS(D13)))) -> 0
... A2025: Zhengbang Group | B2025: Croplands | C2025: Western Europe | D2025: 329 | E2025: Pigmeat | F2025: Nitrogen application | G2025: (t) | H2025: =ROUND(D2025, 3 - LEN(INT(ABS(D2025)))) -> 329

Sheet Milk - Excluding Butter
A1: Company | B1: Land type | C1: Region | D1: Footprint amount | E1: Animal product | F1: Footprint | G1: Unit | H1: Footprint amount (rounded)
A2: Dairy Farmers of America | B2: Grazing | C2: East Asia and Southeast Asia | D2: 2 | E2: Milk - Excluding Butter | F2: Land use | G2: (kha) | H2: =ROUND(D2, 3 - LEN(INT(ABS(D2)))) -> 2
A3: Dairy Farmers of America | B3: Grazing | C3: Eastern Europe | D3: 0 | E3: Milk - Excluding Butter | F3: Land use | G3: (kha) | H3: =ROUND(D3, 3 - LEN(INT(ABS(D3)))) -> 0
A4: Dairy Farmers of America | B4: Grazing | C4: Latin America and the Caribbean | D4: 21 | E4: Milk - Excluding Butter | F4: Land use | G4: (kha) | H4: =ROUND(D4, 3 - LEN(INT(ABS(D4)))) -> 21
A5: Dairy Farmers of America | B5: Grazing | C5: Near East and North Africa | D5: 0 | E5: Milk - Excluding Butter | F5: Land use | G5: (kha) | H5: =ROUND(D5, 3 - LEN(INT(ABS(D5)))) -> 0
A6: Dairy Farmers of America | B6: Grazing | C6: North America | D6: 11506 | E6: Milk - Excluding Butter | F6: Land use | G6: (kha) | H6: =ROUND(D6, 3 - LEN(INT(ABS(D6)))) -> 11500
A7: Dairy Farmers of America | B7: Grazing | C7: Oceania | D7: 15 | E7: Milk - Excluding Butter | F7: Land use | G7: (kha) | H7: =ROUND(D7, 3 - LEN(INT(ABS(D7)))) -> 15
A8: Dairy Farmers of America | B8: Grazing | C8: RoW | D8: 0 | E8: Milk - Excluding Butter | F8: Land use | G8: (kha) | H8: =ROUND(D8, 3 - LEN(INT(ABS(D8)))) -> 0
A9: Dairy Farmers of America | B9: Grazing | C9: Russian Federation | D9: 0 | E9: Milk - Excluding Butter | F9: Land use | G9: (kha) | H9: =ROUND(D9, 3 - LEN(INT(ABS(D9)))) -> 0
A10: Dairy Farmers of America | B10: Grazing | C10: South Asia | D10: 0 | E10: Milk - Excluding Butter | F10: Land use | G10: (kha) | H10: =ROUND(D10, 3 - LEN(INT(ABS(D10)))) -> 0
A11: Dairy Farmers of America | B11: Grazing | C11: Sub-Saharan Africa | D11: 0 | E11: Milk - Excluding Butter | F11: Land use | G11: (kha) | H11: =ROUND(D11, 3 - LEN(INT(ABS(D11)))) -> 0
A12: Dairy Farmers of America | B12: Grazing | C12: Western Europe | D12: 0 | E12: Milk - Excluding Butter | F12: Land use | G12: (kha) | H12: =ROUND(D12, 3 - LEN(INT(ABS(D12)))) -> 0
A13: Dairy Farmers of America | B13: Croplands | C13: East Asia and Southeast Asia | D13: 1 | E13: Milk - Excluding Butter | F13: Land use | G13: (kha) | H13: =ROUND(D13, 3 - LEN(INT(ABS(D13)))) -> 1
... A1409: DMK | B1409: Croplands | C1409: Western Europe | D1409: 24921 | E1409: Milk - Excluding Butter | F1409: Nitrogen application | G1409: (t) | H1409: =ROUND(D1409, 3 - LEN(INT(ABS(D1409)))) -> 24900
